2019-02-12 23:17:25,228 - util.py[DEBUG]: Cloud-init v. 18.2 running 'init-local' at Tue, 12 Feb 2019 23:17:25 +0000. Up 8.32 seconds.
2019-02-12 23:17:25,228 - main.py[DEBUG]: No kernel command line url found.
2019-02-12 23:17:25,228 - main.py[DEBUG]: Closing stdin.
2019-02-12 23:17:25,228 - util.py[DEBUG]: Restoring selinux mode for /var/lib/cloud (recursive=False)
2019-02-12 23:17:25,229 - util.py[DEBUG]: Restoring selinux mode for /var/lib/cloud (recursive=True)
2019-02-12 23:17:25,230 - util.py[DEBUG]: Restoring selinux mode for /var/lib/cloud/scripts (recursive=False)
2019-02-12 23:17:25,230 - util.py[DEBUG]: Restoring selinux mode for /var/lib/cloud/scripts (recursive=True)
2019-02-12 23:17:25,231 - util.py[DEBUG]: Restoring selinux mode for /var/lib/cloud/scripts/per-instance (recursive=False)
2019-02-12 23:17:25,232 - util.py[DEBUG]: Restoring selinux mode for /var/lib/cloud/scripts (recursive=True)
2019-02-12 23:17:25,234 - util.py[DEBUG]: Restoring selinux mode for /var/lib/cloud/scripts/per-once (recursive=False)
2019-02-12 23:17:25,235 - util.py[DEBUG]: Restoring selinux mode for /var/lib/cloud/scripts (recursive=True)
2019-02-12 23:17:25,236 - util.py[DEBUG]: Restoring selinux mode for /var/lib/cloud/scripts/per-boot (recursive=False)
2019-02-12 23:17:25,236 - util.py[DEBUG]: Restoring selinux mode for /var/lib/cloud/scripts (recursive=True)
2019-02-12 23:17:25,237 - util.py[DEBUG]: Restoring selinux mode for /var/lib/cloud/scripts/vendor (recursive=False)
2019-02-12 23:17:25,238 - util.py[DEBUG]: Restoring selinux mode for /var/lib/cloud (recursive=True)
2019-02-12 23:17:25,240 - util.py[DEBUG]: Restoring selinux mode for /var/lib/cloud/seed (recursive=False)
2019-02-12 23:17:25,240 - util.py[DEBUG]: Restoring selinux mode for /var/lib/cloud (recursive=True)
2019-02-12 23:17:25,242 - util.py[DEBUG]: Restoring selinux mode for /var/lib/cloud/instances (recursive=False)
2019-02-12 23:17:25,242 - util.py[DEBUG]: Restoring selinux mode for /var/lib/cloud (recursive=True)
2019-02-12 23:17:25,244 - util.py[DEBUG]: Restoring selinux mode for /var/lib/cloud/handlers (recursive=False)
2019-02-12 23:17:25,245 - util.py[DEBUG]: Restoring selinux mode for /var/lib/cloud (recursive=True)
2019-02-12 23:17:25,247 - util.py[DEBUG]: Restoring selinux mode for /var/lib/cloud/sem (recursive=False)
2019-02-12 23:17:25,247 - util.py[DEBUG]: Restoring selinux mode for /var/lib/cloud/data (recursive=False)
2019-02-12 23:17:25,248 - util.py[DEBUG]: Writing to /var/log/cloud-init.log - ab: [600] 0 bytes
2019-02-12 23:17:25,248 - util.py[DEBUG]: Restoring selinux mode for /var/log/cloud-init.log (recursive=False)
2019-02-12 23:17:25,249 - util.py[DEBUG]: Restoring selinux mode for /var/log/cloud-init.log (recursive=False)
2019-02-12 23:17:25,249 - util.py[DEBUG]: Attempting to remove /var/lib/cloud/instance/boot-finished
2019-02-12 23:17:25,249 - util.py[DEBUG]: Attempting to remove /var/lib/cloud/data/no-net
2019-02-12 23:17:25,249 - handlers.py[DEBUG]: start: init-local/check-cache: attempting to read from cache [check]
2019-02-12 23:17:25,249 - util.py[DEBUG]: Reading from /var/lib/cloud/instance/obj.pkl (quiet=False)
2019-02-12 23:17:25,250 - stages.py[DEBUG]: no cache found
2019-02-12 23:17:25,250 - handlers.py[DEBUG]: finish: init-local/check-cache: SUCCESS: no cache found
2019-02-12 23:17:25,250 - util.py[DEBUG]: Attempting to remove /var/lib/cloud/instance
2019-02-12 23:17:25,254 - stages.py[DEBUG]: Using distro class <class 'cloudinit.distros.rhel.Distro'>
2019-02-12 23:17:25,254 - __init__.py[DEBUG]: Looking for data source in: ['NoCloud', 'ConfigDrive', 'OpenNebula', 'DigitalOcean', 'Azure', 'AltCloud', 'OVF', 'MAAS', 'GCE', 'OpenStack', 'AliYun', 'Ec2', 'CloudSigma', 'CloudStack', 'SmartOS', 'Bigstep', 'Scaleway', 'Hetzner', 'IBMCloud', 'None'], via packages ['', u'cloudinit.sources'] that matches dependencies ['FILESYSTEM']
2019-02-12 23:17:25,320 - __init__.py[DEBUG]: Searching for local data source in: [u'DataSourceNoCloud', u'DataSourceConfigDrive', u'DataSourceOpenNebula', u'DataSourceDigitalOcean', u'DataSourceAzure', u'DataSourceOVF', u'DataSourceEc2Local', u'DataSourceCloudSigma', u'DataSourceSmartOS', u'DataSourceHetzner', u'DataSourceIBMCloud']
2019-02-12 23:17:25,320 - handlers.py[DEBUG]: start: init-local/search-NoCloud: searching for local data from DataSourceNoCloud
2019-02-12 23:17:25,320 - __init__.py[DEBUG]: Seeing if we can get any data from <class 'cloudinit.sources.DataSourceNoCloud.DataSourceNoCloud'>
2019-02-12 23:17:25,320 - util.py[DEBUG]: Running command ['systemd-detect-virt', '--quiet', '--container'] with allowed return codes [0] (shell=False, capture=True)
2019-02-12 23:17:25,323 - util.py[DEBUG]: Running command ['running-in-container'] with allowed return codes [0] (shell=False, capture=True)
2019-02-12 23:17:25,326 - util.py[DEBUG]: Running command ['lxc-is-container'] with allowed return codes [0] (shell=False, capture=True)
2019-02-12 23:17:25,328 - util.py[DEBUG]: Reading from /proc/1/environ (quiet=False)
2019-02-12 23:17:25,329 - util.py[DEBUG]: Read 0 bytes from /proc/1/environ
2019-02-12 23:17:25,329 - util.py[DEBUG]: Reading from /proc/self/status (quiet=False)
2019-02-12 23:17:25,329 - util.py[DEBUG]: Read 1189 bytes from /proc/self/status
2019-02-12 23:17:25,329 - util.py[DEBUG]: querying dmi data /sys/class/dmi/id/product_serial
2019-02-12 23:17:25,329 - util.py[DEBUG]: Reading from /sys/class/dmi/id/product_serial (quiet=False)
2019-02-12 23:17:25,330 - util.py[DEBUG]: Read 37 bytes from /sys/class/dmi/id/product_serial
2019-02-12 23:17:25,330 - util.py[DEBUG]: dmi data /sys/class/dmi/id/product_serial returned ec2d7ef2-3f58-4ce0-ff3a-8ddf8d41b58b
2019-02-12 23:17:25,330 - util.py[DEBUG]: Reading from /var/lib/cloud/seed/nocloud/user-data (quiet=False)
2019-02-12 23:17:25,330 - util.py[DEBUG]: Reading from /var/lib/cloud/seed/nocloud/meta-data (quiet=False)
2019-02-12 23:17:25,330 - util.py[DEBUG]: Reading from /var/lib/cloud/seed/nocloud/vendor-data (quiet=False)
2019-02-12 23:17:25,330 - util.py[DEBUG]: Reading from /var/lib/cloud/seed/nocloud/network-config (quiet=False)
2019-02-12 23:17:25,330 - util.py[DEBUG]: Reading from /var/lib/cloud/seed/nocloud-net/user-data (quiet=False)
2019-02-12 23:17:25,330 - util.py[DEBUG]: Reading from /var/lib/cloud/seed/nocloud-net/meta-data (quiet=False)
2019-02-12 23:17:25,330 - util.py[DEBUG]: Reading from /var/lib/cloud/seed/nocloud-net/vendor-data (quiet=False)
2019-02-12 23:17:25,330 - util.py[DEBUG]: Reading from /var/lib/cloud/seed/nocloud-net/network-config (quiet=False)
2019-02-12 23:17:25,330 - util.py[DEBUG]: Running command ['blkid', '-odevice', '/dev/sr0'] with allowed return codes [0, 2] (shell=False, capture=True)
2019-02-12 23:17:25,337 - util.py[DEBUG]: Running command ['blkid', '-odevice', '/dev/sr1'] with allowed return codes [0, 2] (shell=False, capture=True)
2019-02-12 23:17:25,340 - util.py[DEBUG]: Running command ['blkid', '-tTYPE=vfat', '-odevice'] with allowed return codes [0, 2] (shell=False, capture=True)
2019-02-12 23:17:25,352 - util.py[DEBUG]: Running command ['blkid', '-tTYPE=iso9660', '-odevice'] with allowed return codes [0, 2] (shell=False, capture=True)
2019-02-12 23:17:25,355 - util.py[DEBUG]: Running command ['blkid', '-tLABEL=cidata', '-odevice'] with allowed return codes [0, 2] (shell=False, capture=True)
2019-02-12 23:17:25,357 - handlers.py[DEBUG]: finish: init-local/search-NoCloud: SUCCESS: no local data found from DataSourceNoCloud
2019-02-12 23:17:25,357 - handlers.py[DEBUG]: start: init-local/search-ConfigDrive: searching for local data from DataSourceConfigDrive
2019-02-12 23:17:25,357 - __init__.py[DEBUG]: Seeing if we can get any data from <class 'cloudinit.sources.DataSourceConfigDrive.DataSourceConfigDrive'>
2019-02-12 23:17:25,358 - util.py[DEBUG]: Running command ['blkid', '-odevice', '/dev/sr0'] with allowed return codes [0, 2] (shell=False, capture=True)
2019-02-12 23:17:25,360 - util.py[DEBUG]: Running command ['blkid', '-odevice', '/dev/sr1'] with allowed return codes [0, 2] (shell=False, capture=True)
2019-02-12 23:17:25,362 - util.py[DEBUG]: Running command ['blkid', '-odevice', '/dev/cd0'] with allowed return codes [0, 2] (shell=False, capture=True)
2019-02-12 23:17:25,364 - util.py[DEBUG]: Running command ['blkid', '-odevice', '/dev/cd1'] with allowed return codes [0, 2] (shell=False, capture=True)
2019-02-12 23:17:25,367 - util.py[DEBUG]: Running command ['blkid', '-tTYPE=vfat', '-odevice'] with allowed return codes [0, 2] (shell=False, capture=True)
2019-02-12 23:17:25,369 - util.py[DEBUG]: Running command ['blkid', '-tTYPE=iso9660', '-odevice'] with allowed return codes [0, 2] (shell=False, capture=True)
2019-02-12 23:17:25,371 - util.py[DEBUG]: Running command ['blkid', '-tLABEL=config-2', '-odevice'] with allowed return codes [0, 2] (shell=False, capture=True)
2019-02-12 23:17:25,374 - util.py[DEBUG]: Running command ['blkid', '-tLABEL=CONFIG-2', '-odevice'] with allowed return codes [0, 2] (shell=False, capture=True)
2019-02-12 23:17:25,376 - handlers.py[DEBUG]: finish: init-local/search-ConfigDrive: SUCCESS: no local data found from DataSourceConfigDrive
2019-02-12 23:17:25,376 - handlers.py[DEBUG]: start: init-local/search-OpenNebula: searching for local data from DataSourceOpenNebula
2019-02-12 23:17:25,376 - __init__.py[DEBUG]: Seeing if we can get any data from <class 'cloudinit.sources.DataSourceOpenNebula.DataSourceOpenNebula'>
2019-02-12 23:17:25,377 - util.py[DEBUG]: Running command ['blkid', '-tLABEL=CONTEXT', '-odevice'] with allowed return codes [0, 2] (shell=False, capture=True)
2019-02-12 23:17:25,379 - util.py[DEBUG]: Running command ['blkid', '-tLABEL=CDROM', '-odevice'] with allowed return codes [0, 2] (shell=False, capture=True)
2019-02-12 23:17:25,381 - util.py[DEBUG]: Running command ['blkid', '-tTYPE=iso9660', '-odevice'] with allowed return codes [0, 2] (shell=False, capture=True)
2019-02-12 23:17:25,384 - handlers.py[DEBUG]: finish: init-local/search-OpenNebula: SUCCESS: no local data found from DataSourceOpenNebula
2019-02-12 23:17:25,384 - handlers.py[DEBUG]: start: init-local/search-DigitalOcean: searching for local data from DataSourceDigitalOcean
2019-02-12 23:17:25,384 - __init__.py[DEBUG]: Seeing if we can get any data from <class 'cloudinit.sources.DataSourceDigitalOcean.DataSourceDigitalOcean'>
2019-02-12 23:17:25,384 - util.py[DEBUG]: Running command ['systemd-detect-virt', '--quiet', '--container'] with allowed return codes [0] (shell=False, capture=True)
2019-02-12 23:17:25,387 - util.py[DEBUG]: Running command ['running-in-container'] with allowed return codes [0] (shell=False, capture=True)
2019-02-12 23:17:25,390 - util.py[DEBUG]: Running command ['lxc-is-container'] with allowed return codes [0] (shell=False, capture=True)
2019-02-12 23:17:25,392 - util.py[DEBUG]: Reading from /proc/1/environ (quiet=False)
2019-02-12 23:17:25,392 - util.py[DEBUG]: Read 0 bytes from /proc/1/environ
2019-02-12 23:17:25,392 - util.py[DEBUG]: Reading from /proc/self/status (quiet=False)
2019-02-12 23:17:25,393 - util.py[DEBUG]: Read 1189 bytes from /proc/self/status
2019-02-12 23:17:25,393 - util.py[DEBUG]: querying dmi data /sys/class/dmi/id/sys_vendor
2019-02-12 23:17:25,393 - util.py[DEBUG]: Reading from /sys/class/dmi/id/sys_vendor (quiet=False)
2019-02-12 23:17:25,393 - util.py[DEBUG]: Read 4 bytes from /sys/class/dmi/id/sys_vendor
2019-02-12 23:17:25,393 - util.py[DEBUG]: dmi data /sys/class/dmi/id/sys_vendor returned Xen
2019-02-12 23:17:25,393 - handlers.py[DEBUG]: finish: init-local/search-DigitalOcean: SUCCESS: no local data found from DataSourceDigitalOcean
2019-02-12 23:17:25,393 - handlers.py[DEBUG]: start: init-local/search-Azure: searching for local data from DataSourceAzure
2019-02-12 23:17:25,394 - __init__.py[DEBUG]: Seeing if we can get any data from <class 'cloudinit.sources.DataSourceAzure.DataSourceAzure'>
2019-02-12 23:17:25,394 - util.py[DEBUG]: Running command ['systemd-detect-virt', '--quiet', '--container'] with allowed return codes [0] (shell=False, capture=True)
2019-02-12 23:17:25,396 - util.py[DEBUG]: Running command ['running-in-container'] with allowed return codes [0] (shell=False, capture=True)
2019-02-12 23:17:25,399 - util.py[DEBUG]: Running command ['lxc-is-container'] with allowed return codes [0] (shell=False, capture=True)
2019-02-12 23:17:25,402 - util.py[DEBUG]: Reading from /proc/1/environ (quiet=False)
2019-02-12 23:17:25,402 - util.py[DEBUG]: Read 0 bytes from /proc/1/environ
2019-02-12 23:17:25,402 - util.py[DEBUG]: Reading from /proc/self/status (quiet=False)
2019-02-12 23:17:25,402 - util.py[DEBUG]: Read 1189 bytes from /proc/self/status
2019-02-12 23:17:25,402 - util.py[DEBUG]: querying dmi data /sys/class/dmi/id/chassis_asset_tag
2019-02-12 23:17:25,402 - util.py[DEBUG]: Reading from /sys/class/dmi/id/chassis_asset_tag (quiet=False)
2019-02-12 23:17:25,402 - util.py[DEBUG]: Read 1 bytes from /sys/class/dmi/id/chassis_asset_tag
2019-02-12 23:17:25,402 - util.py[DEBUG]: dmi data /sys/class/dmi/id/chassis_asset_tag returned 
2019-02-12 23:17:25,402 - DataSourceAzure.py[DEBUG]: Non-Azure DMI asset tag '' discovered.
2019-02-12 23:17:25,403 - handlers.py[DEBUG]: finish: init-local/search-Azure: SUCCESS: no local data found from DataSourceAzure
2019-02-12 23:17:25,403 - handlers.py[DEBUG]: start: init-local/search-OVF: searching for local data from DataSourceOVF
2019-02-12 23:17:25,403 - __init__.py[DEBUG]: Seeing if we can get any data from <class 'cloudinit.sources.DataSourceOVF.DataSourceOVF'>
2019-02-12 23:17:25,403 - util.py[DEBUG]: Running command ['systemd-detect-virt', '--quiet', '--container'] with allowed return codes [0] (shell=False, capture=True)
2019-02-12 23:17:25,405 - util.py[DEBUG]: Running command ['running-in-container'] with allowed return codes [0] (shell=False, capture=True)
2019-02-12 23:17:25,408 - util.py[DEBUG]: Running command ['lxc-is-container'] with allowed return codes [0] (shell=False, capture=True)
2019-02-12 23:17:25,411 - util.py[DEBUG]: Reading from /proc/1/environ (quiet=False)
2019-02-12 23:17:25,411 - util.py[DEBUG]: Read 0 bytes from /proc/1/environ
2019-02-12 23:17:25,411 - util.py[DEBUG]: Reading from /proc/self/status (quiet=False)
2019-02-12 23:17:25,411 - util.py[DEBUG]: Read 1189 bytes from /proc/self/status
2019-02-12 23:17:25,411 - util.py[DEBUG]: querying dmi data /sys/class/dmi/id/product_name
2019-02-12 23:17:25,411 - util.py[DEBUG]: Reading from /sys/class/dmi/id/product_name (quiet=False)
2019-02-12 23:17:25,411 - util.py[DEBUG]: Read 9 bytes from /sys/class/dmi/id/product_name
2019-02-12 23:17:25,411 - util.py[DEBUG]: dmi data /sys/class/dmi/id/product_name returned HVM domU
2019-02-12 23:17:25,411 - util.py[DEBUG]: Reading from /proc/mounts (quiet=False)
2019-02-12 23:17:25,412 - util.py[DEBUG]: Read 2222 bytes from /proc/mounts
2019-02-12 23:17:25,412 - util.py[DEBUG]: Fetched {'configfs': {'mountpoint': '/sys/kernel/config', 'opts': 'rw,relatime', 'fstype': 'configfs'}, 'devpts': {'mountpoint': '/dev/pts', 'opts': 'rw,seclabel,nosuid,noexec,relatime,gid=5,mode=620,ptmxmode=000', 'fstype': 'devpts'}, 'debugfs': {'mountpoint': '/sys/kernel/debug', 'opts': 'rw,relatime', 'fstype': 'debugfs'}, 'securityfs': {'mountpoint': '/sys/kernel/security', 'opts': 'rw,nosuid,nodev,noexec,relatime', 'fstype': 'securityfs'}, 'sysfs': {'mountpoint': '/sys', 'opts': 'rw,seclabel,nosuid,nodev,noexec,relatime', 'fstype': 'sysfs'}, 'mqueue': {'mountpoint': '/dev/mqueue', 'opts': 'rw,seclabel,relatime', 'fstype': 'mqueue'}, 'pstore': {'mountpoint': '/sys/fs/pstore', 'opts': 'rw,nosuid,nodev,noexec,relatime', 'fstype': 'pstore'}, 'rpc_pipefs': {'mountpoint': '/var/lib/nfs/rpc_pipefs', 'opts': 'rw,relatime', 'fstype': 'rpc_pipefs'}, 'hugetlbfs': {'mountpoint': '/dev/hugepages', 'opts': 'rw,seclabel,relatime', 'fstype': 'hugetlbfs'}, '/dev/xvda1': {'mountpoint': '/', 'opts': 'rw,seclabel,relatime,attr2,inode64,noquota', 'fstype': 'xfs'}, 'systemd-1': {'mountpoint': '/proc/sys/fs/binfmt_misc', 'opts': 'rw,relatime,fd=30,pgrp=1,timeout=0,minproto=5,maxproto=5,direct,pipe_ino=17333', 'fstype': 'autofs'}, 'cgroup': {'mountpoint': '/sys/fs/cgroup/cpuset', 'opts': 'rw,seclabel,nosuid,nodev,noexec,relatime,cpuset', 'fstype': 'cgroup'}, 'tmpfs': {'mountpoint': '/sys/fs/cgroup', 'opts': 'ro,seclabel,nosuid,nodev,noexec,mode=755', 'fstype': 'tmpfs'}, 'proc': {'mountpoint': '/proc', 'opts': 'rw,nosuid,nodev,noexec,relatime', 'fstype': 'proc'}, 'devtmpfs': {'mountpoint': '/dev', 'opts': 'rw,seclabel,nosuid,size=483740k,nr_inodes=120935,mode=755', 'fstype': 'devtmpfs'}, 'selinuxfs': {'mountpoint': '/sys/fs/selinux', 'opts': 'rw,relatime', 'fstype': 'selinuxfs'}, 'rootfs': {'mountpoint': '/', 'opts': 'rw', 'fstype': 'rootfs'}} mounts from proc
2019-02-12 23:17:25,412 - util.py[DEBUG]: Running command ['blkid', '-tTYPE=iso9660', '-odevice'] with allowed return codes [0, 2] (shell=False, capture=True)
2019-02-12 23:17:25,414 - handlers.py[DEBUG]: finish: init-local/search-OVF: SUCCESS: no local data found from DataSourceOVF
2019-02-12 23:17:25,415 - handlers.py[DEBUG]: start: init-local/search-Ec2Local: searching for local data from DataSourceEc2Local
2019-02-12 23:17:25,415 - __init__.py[DEBUG]: Seeing if we can get any data from <class 'cloudinit.sources.DataSourceEc2.DataSourceEc2Local'>
2019-02-12 23:17:25,415 - util.py[DEBUG]: Reading from /sys/hypervisor/uuid (quiet=False)
2019-02-12 23:17:25,415 - util.py[DEBUG]: Read 37 bytes from /sys/hypervisor/uuid
2019-02-12 23:17:25,415 - util.py[DEBUG]: Running command ['systemd-detect-virt', '--quiet', '--container'] with allowed return codes [0] (shell=False, capture=True)
2019-02-12 23:17:25,417 - util.py[DEBUG]: Running command ['running-in-container'] with allowed return codes [0] (shell=False, capture=True)
2019-02-12 23:17:25,420 - util.py[DEBUG]: Running command ['lxc-is-container'] with allowed return codes [0] (shell=False, capture=True)
2019-02-12 23:17:25,423 - util.py[DEBUG]: Reading from /proc/1/environ (quiet=False)
2019-02-12 23:17:25,423 - util.py[DEBUG]: Read 0 bytes from /proc/1/environ
2019-02-12 23:17:25,423 - util.py[DEBUG]: Reading from /proc/self/status (quiet=False)
2019-02-12 23:17:25,423 - util.py[DEBUG]: Read 1189 bytes from /proc/self/status
2019-02-12 23:17:25,423 - util.py[DEBUG]: querying dmi data /sys/class/dmi/id/product_serial
2019-02-12 23:17:25,423 - util.py[DEBUG]: Reading from /sys/class/dmi/id/product_serial (quiet=False)
2019-02-12 23:17:25,423 - util.py[DEBUG]: Read 37 bytes from /sys/class/dmi/id/product_serial
2019-02-12 23:17:25,423 - util.py[DEBUG]: dmi data /sys/class/dmi/id/product_serial returned ec2d7ef2-3f58-4ce0-ff3a-8ddf8d41b58b
2019-02-12 23:17:25,423 - util.py[DEBUG]: Reading from /var/lib/cloud/seed/ec2/meta-data (quiet=False)
2019-02-12 23:17:25,424 - DataSourceEc2.py[DEBUG]: strict_mode: warn, cloud_platform=AWS
2019-02-12 23:17:25,424 - util.py[DEBUG]: Reading from /sys/class/net/eth0/carrier (quiet=False)
2019-02-12 23:17:25,424 - util.py[DEBUG]: Reading from /sys/class/net/eth0/dormant (quiet=False)
2019-02-12 23:17:25,424 - util.py[DEBUG]: Reading from /sys/class/net/eth0/operstate (quiet=False)
2019-02-12 23:17:25,424 - util.py[DEBUG]: Read 5 bytes from /sys/class/net/eth0/operstate
2019-02-12 23:17:25,424 - util.py[DEBUG]: Reading from /sys/class/net/eth0/address (quiet=False)
2019-02-12 23:17:25,425 - util.py[DEBUG]: Read 18 bytes from /sys/class/net/eth0/address
2019-02-12 23:17:25,426 - dhcp.py[DEBUG]: Performing a dhcp discovery on eth0
2019-02-12 23:17:25,426 - util.py[DEBUG]: Copying /usr/sbin/dhclient to /var/tmp/cloud-init/cloud-init-dhcp-MMt98X/dhclient
2019-02-12 23:17:25,428 - util.py[DEBUG]: Running command ['ip', 'link', 'set', 'dev', 'eth0', 'up'] with allowed return codes [0] (shell=False, capture=True)
2019-02-12 23:17:25,436 - util.py[DEBUG]: Running command ['/var/tmp/cloud-init/cloud-init-dhcp-MMt98X/dhclient', '-1', '-v', '-lf', '/var/tmp/cloud-init/cloud-init-dhcp-MMt98X/dhcp.leases', '-pf', '/var/tmp/cloud-init/cloud-init-dhcp-MMt98X/dhclient.pid', 'eth0', '-sf', '/bin/true'] with allowed return codes [0] (shell=False, capture=True)
2019-02-12 23:17:25,478 - util.py[DEBUG]: All files appeared after 0 seconds: ['/var/tmp/cloud-init/cloud-init-dhcp-MMt98X/dhclient.pid', '/var/tmp/cloud-init/cloud-init-dhcp-MMt98X/dhcp.leases']
2019-02-12 23:17:25,478 - util.py[DEBUG]: Reading from /var/tmp/cloud-init/cloud-init-dhcp-MMt98X/dhclient.pid (quiet=False)
2019-02-12 23:17:25,478 - util.py[DEBUG]: Read 5 bytes from /var/tmp/cloud-init/cloud-init-dhcp-MMt98X/dhclient.pid
2019-02-12 23:17:25,479 - util.py[DEBUG]: Reading from /var/tmp/cloud-init/cloud-init-dhcp-MMt98X/dhcp.leases (quiet=False)
2019-02-12 23:17:25,479 - util.py[DEBUG]: Read 516 bytes from /var/tmp/cloud-init/cloud-init-dhcp-MMt98X/dhcp.leases
2019-02-12 23:17:25,479 - dhcp.py[DEBUG]: Received dhcp lease on eth0 for 172.31.84.133/255.255.240.0
2019-02-12 23:17:25,479 - __init__.py[DEBUG]: Attempting setup of ephemeral network on eth0 with 172.31.84.133/20 brd 172.31.95.255
2019-02-12 23:17:25,479 - util.py[DEBUG]: Running command ['ip', '-family', 'inet', 'addr', 'add', '172.31.84.133/20', 'broadcast', '172.31.95.255', 'dev', 'eth0'] with allowed return codes [0] (shell=False, capture=True)
2019-02-12 23:17:25,482 - util.py[DEBUG]: Running command ['ip', '-family', 'inet', 'link', 'set', 'dev', 'eth0', 'up'] with allowed return codes [0] (shell=False, capture=True)
2019-02-12 23:17:25,489 - util.py[DEBUG]: Running command ['ip', 'route', 'show', '0.0.0.0/0'] with allowed return codes [0] (shell=False, capture=True)
2019-02-12 23:17:25,491 - util.py[DEBUG]: Running command ['ip', '-4', 'route', 'add', 'default', 'via', '172.31.80.1', 'dev', 'eth0'] with allowed return codes [0] (shell=False, capture=True)
2019-02-12 23:18:15,547 - DataSourceEc2.py[DEBUG]: Removed the following from metadata urls: ['http://instance-data.:8773']
2019-02-12 23:18:15,547 - url_helper.py[DEBUG]: [0/1] open 'http://169.254.169.254/2009-04-04/meta-data/instance-id' with {'url': 'http://169.254.169.254/2009-04-04/meta-data/instance-id', 'headers': {'User-Agent': 'Cloud-Init/18.2'}, 'allow_redirects': True, 'method': 'GET', 'timeout': 50.0} configuration
2019-02-12 23:18:15,573 - url_helper.py[DEBUG]: Read from http://169.254.169.254/2009-04-04/meta-data/instance-id (200, 19b) after 1 attempts
2019-02-12 23:18:15,573 - DataSourceEc2.py[DEBUG]: Using metadata source: 'http://169.254.169.254'
2019-02-12 23:18:15,573 - url_helper.py[DEBUG]: [0/1] open 'http://169.254.169.254/2016-09-02/meta-data/instance-id' with {'url': 'http://169.254.169.254/2016-09-02/meta-data/instance-id', 'headers': {'User-Agent': 'Cloud-Init/18.2'}, 'allow_redirects': True, 'method': 'GET'} configuration
2019-02-12 23:18:15,575 - url_helper.py[DEBUG]: Read from http://169.254.169.254/2016-09-02/meta-data/instance-id (200, 19b) after 1 attempts
2019-02-12 23:18:15,575 - DataSourceEc2.py[DEBUG]: Found preferred metadata version 2016-09-02
2019-02-12 23:18:15,575 - url_helper.py[DEBUG]: [0/6] open 'http://169.254.169.254/2016-09-02/user-data' with {'url': 'http://169.254.169.254/2016-09-02/user-data', 'headers': {'User-Agent': 'Cloud-Init/18.2'}, 'allow_redirects': True, 'method': 'GET', 'timeout': 5.0} configuration
2019-02-12 23:18:15,578 - url_helper.py[DEBUG]: [0/6] open 'http://169.254.169.254/2016-09-02/meta-data/' with {'url': 'http://169.254.169.254/2016-09-02/meta-data/', 'headers': {'User-Agent': 'Cloud-Init/18.2'}, 'allow_redirects': True, 'method': 'GET', 'timeout': 5.0} configuration
2019-02-12 23:18:15,580 - url_helper.py[DEBUG]: Read from http://169.254.169.254/2016-09-02/meta-data/ (200, 277b) after 1 attempts
2019-02-12 23:18:15,580 - url_helper.py[DEBUG]: [0/6] open 'http://169.254.169.254/2016-09-02/meta-data/block-device-mapping/' with {'url': 'http://169.254.169.254/2016-09-02/meta-data/block-device-mapping/', 'headers': {'User-Agent': 'Cloud-Init/18.2'}, 'allow_redirects': True, 'method': 'GET', 'timeout': 5.0} configuration
2019-02-12 23:18:15,582 - url_helper.py[DEBUG]: Read from http://169.254.169.254/2016-09-02/meta-data/block-device-mapping/ (200, 8b) after 1 attempts
2019-02-12 23:18:15,582 - url_helper.py[DEBUG]: [0/6] open 'http://169.254.169.254/2016-09-02/meta-data/block-device-mapping/ami' with {'url': 'http://169.254.169.254/2016-09-02/meta-data/block-device-mapping/ami', 'headers': {'User-Agent': 'Cloud-Init/18.2'}, 'allow_redirects': True, 'method': 'GET', 'timeout': 5.0} configuration
2019-02-12 23:18:15,585 - url_helper.py[DEBUG]: Read from http://169.254.169.254/2016-09-02/meta-data/block-device-mapping/ami (200, 9b) after 1 attempts
2019-02-12 23:18:15,585 - url_helper.py[DEBUG]: [0/6] open 'http://169.254.169.254/2016-09-02/meta-data/block-device-mapping/root' with {'url': 'http://169.254.169.254/2016-09-02/meta-data/block-device-mapping/root', 'headers': {'User-Agent': 'Cloud-Init/18.2'}, 'allow_redirects': True, 'method': 'GET', 'timeout': 5.0} configuration
2019-02-12 23:18:15,587 - url_helper.py[DEBUG]: Read from http://169.254.169.254/2016-09-02/meta-data/block-device-mapping/root (200, 9b) after 1 attempts
2019-02-12 23:18:15,587 - url_helper.py[DEBUG]: [0/6] open 'http://169.254.169.254/2016-09-02/meta-data/metrics/' with {'url': 'http://169.254.169.254/2016-09-02/meta-data/metrics/', 'headers': {'User-Agent': 'Cloud-Init/18.2'}, 'allow_redirects': True, 'method': 'GET', 'timeout': 5.0} configuration
2019-02-12 23:18:15,589 - url_helper.py[DEBUG]: Read from http://169.254.169.254/2016-09-02/meta-data/metrics/ (200, 7b) after 1 attempts
2019-02-12 23:18:15,589 - url_helper.py[DEBUG]: [0/6] open 'http://169.254.169.254/2016-09-02/meta-data/metrics/vhostmd' with {'url': 'http://169.254.169.254/2016-09-02/meta-data/metrics/vhostmd', 'headers': {'User-Agent': 'Cloud-Init/18.2'}, 'allow_redirects': True, 'method': 'GET', 'timeout': 5.0} configuration
2019-02-12 23:18:15,592 - url_helper.py[DEBUG]: Read from http://169.254.169.254/2016-09-02/meta-data/metrics/vhostmd (200, 38b) after 1 attempts
2019-02-12 23:18:15,592 - url_helper.py[DEBUG]: [0/6] open 'http://169.254.169.254/2016-09-02/meta-data/network/' with {'url': 'http://169.254.169.254/2016-09-02/meta-data/network/', 'headers': {'User-Agent': 'Cloud-Init/18.2'}, 'allow_redirects': True, 'method': 'GET', 'timeout': 5.0} configuration
2019-02-12 23:18:15,594 - url_helper.py[DEBUG]: Read from http://169.254.169.254/2016-09-02/meta-data/network/ (200, 11b) after 1 attempts
2019-02-12 23:18:15,594 - url_helper.py[DEBUG]: [0/6] open 'http://169.254.169.254/2016-09-02/meta-data/network/interfaces/' with {'url': 'http://169.254.169.254/2016-09-02/meta-data/network/interfaces/', 'headers': {'User-Agent': 'Cloud-Init/18.2'}, 'allow_redirects': True, 'method': 'GET', 'timeout': 5.0} configuration
2019-02-12 23:18:15,596 - url_helper.py[DEBUG]: Read from http://169.254.169.254/2016-09-02/meta-data/network/interfaces/ (200, 5b) after 1 attempts
2019-02-12 23:18:15,597 - url_helper.py[DEBUG]: [0/6] open 'http://169.254.169.254/2016-09-02/meta-data/network/interfaces/macs/' with {'url': 'http://169.254.169.254/2016-09-02/meta-data/network/interfaces/macs/', 'headers': {'User-Agent': 'Cloud-Init/18.2'}, 'allow_redirects': True, 'method': 'GET', 'timeout': 5.0} configuration
2019-02-12 23:18:15,599 - url_helper.py[DEBUG]: Read from http://169.254.169.254/2016-09-02/meta-data/network/interfaces/macs/ (200, 18b) after 1 attempts
2019-02-12 23:18:15,599 - url_helper.py[DEBUG]: [0/6] open 'http://169.254.169.254/2016-09-02/meta-data/network/interfaces/macs/12:4d:02:3b:2f:5e/' with {'url': 'http://169.254.169.254/2016-09-02/meta-data/network/interfaces/macs/12:4d:02:3b:2f:5e/', 'headers': {'User-Agent': 'Cloud-Init/18.2'}, 'allow_redirects': True, 'method': 'GET', 'timeout': 5.0} configuration
2019-02-12 23:18:15,601 - url_helper.py[DEBUG]: Read from http://169.254.169.254/2016-09-02/meta-data/network/interfaces/macs/12:4d:02:3b:2f:5e/ (200, 230b) after 1 attempts
2019-02-12 23:18:15,601 - url_helper.py[DEBUG]: [0/6] open 'http://169.254.169.254/2016-09-02/meta-data/network/interfaces/macs/12:4d:02:3b:2f:5e/ipv4-associations/' with {'url': 'http://169.254.169.254/2016-09-02/meta-data/network/interfaces/macs/12:4d:02:3b:2f:5e/ipv4-associations/', 'headers': {'User-Agent': 'Cloud-Init/18.2'}, 'allow_redirects': True, 'method': 'GET', 'timeout': 5.0} configuration
2019-02-12 23:18:15,603 - url_helper.py[DEBUG]: Read from http://169.254.169.254/2016-09-02/meta-data/network/interfaces/macs/12:4d:02:3b:2f:5e/ipv4-associations/ (200, 13b) after 1 attempts
2019-02-12 23:18:15,604 - url_helper.py[DEBUG]: [0/6] open 'http://169.254.169.254/2016-09-02/meta-data/network/interfaces/macs/12:4d:02:3b:2f:5e/ipv4-associations/52.91.211.198' with {'url': 'http://169.254.169.254/2016-09-02/meta-data/network/interfaces/macs/12:4d:02:3b:2f:5e/ipv4-associations/52.91.211.198', 'headers': {'User-Agent': 'Cloud-Init/18.2'}, 'allow_redirects': True, 'method': 'GET', 'timeout': 5.0} configuration
2019-02-12 23:18:15,606 - url_helper.py[DEBUG]: Read from http://169.254.169.254/2016-09-02/meta-data/network/interfaces/macs/12:4d:02:3b:2f:5e/ipv4-associations/52.91.211.198 (200, 13b) after 1 attempts
2019-02-12 23:18:15,606 - url_helper.py[DEBUG]: [0/6] open 'http://169.254.169.254/2016-09-02/meta-data/network/interfaces/macs/12:4d:02:3b:2f:5e/local-hostname' with {'url': 'http://169.254.169.254/2016-09-02/meta-data/network/interfaces/macs/12:4d:02:3b:2f:5e/local-hostname', 'headers': {'User-Agent': 'Cloud-Init/18.2'}, 'allow_redirects': True, 'method': 'GET', 'timeout': 5.0} configuration
2019-02-12 23:18:15,608 - url_helper.py[DEBUG]: Read from http://169.254.169.254/2016-09-02/meta-data/network/interfaces/macs/12:4d:02:3b:2f:5e/local-hostname (200, 29b) after 1 attempts
2019-02-12 23:18:15,608 - url_helper.py[DEBUG]: [0/6] open 'http://169.254.169.254/2016-09-02/meta-data/network/interfaces/macs/12:4d:02:3b:2f:5e/security-groups' with {'url': 'http://169.254.169.254/2016-09-02/meta-data/network/interfaces/macs/12:4d:02:3b:2f:5e/security-groups', 'headers': {'User-Agent': 'Cloud-Init/18.2'}, 'allow_redirects': True, 'method': 'GET', 'timeout': 5.0} configuration
2019-02-12 23:18:15,610 - url_helper.py[DEBUG]: Read from http://169.254.169.254/2016-09-02/meta-data/network/interfaces/macs/12:4d:02:3b:2f:5e/security-groups (200, 61b) after 1 attempts
2019-02-12 23:18:15,611 - url_helper.py[DEBUG]: [0/6] open 'http://169.254.169.254/2016-09-02/meta-data/network/interfaces/macs/12:4d:02:3b:2f:5e/public-hostname' with {'url': 'http://169.254.169.254/2016-09-02/meta-data/network/interfaces/macs/12:4d:02:3b:2f:5e/public-hostname', 'headers': {'User-Agent': 'Cloud-Init/18.2'}, 'allow_redirects': True, 'method': 'GET', 'timeout': 5.0} configuration
2019-02-12 23:18:15,613 - url_helper.py[DEBUG]: Read from http://169.254.169.254/2016-09-02/meta-data/network/interfaces/macs/12:4d:02:3b:2f:5e/public-hostname (200, 41b) after 1 attempts
2019-02-12 23:18:15,613 - url_helper.py[DEBUG]: [0/6] open 'http://169.254.169.254/2016-09-02/meta-data/network/interfaces/macs/12:4d:02:3b:2f:5e/vpc-ipv4-cidr-blocks' with {'url': 'http://169.254.169.254/2016-09-02/meta-data/network/interfaces/macs/12:4d:02:3b:2f:5e/vpc-ipv4-cidr-blocks', 'headers': {'User-Agent': 'Cloud-Init/18.2'}, 'allow_redirects': True, 'method': 'GET', 'timeout': 5.0} configuration
2019-02-12 23:18:15,615 - url_helper.py[DEBUG]: Read from http://169.254.169.254/2016-09-02/meta-data/network/interfaces/macs/12:4d:02:3b:2f:5e/vpc-ipv4-cidr-blocks (200, 13b) after 1 attempts
2019-02-12 23:18:15,615 - url_helper.py[DEBUG]: [0/6] open 'http://169.254.169.254/2016-09-02/meta-data/network/interfaces/macs/12:4d:02:3b:2f:5e/subnet-id' with {'url': 'http://169.254.169.254/2016-09-02/meta-data/network/interfaces/macs/12:4d:02:3b:2f:5e/subnet-id', 'headers': {'User-Agent': 'Cloud-Init/18.2'}, 'allow_redirects': True, 'method': 'GET', 'timeout': 5.0} configuration
2019-02-12 23:18:15,617 - url_helper.py[DEBUG]: Read from http://169.254.169.254/2016-09-02/meta-data/network/interfaces/macs/12:4d:02:3b:2f:5e/subnet-id (200, 15b) after 1 attempts
2019-02-12 23:18:15,618 - url_helper.py[DEBUG]: [0/6] open 'http://169.254.169.254/2016-09-02/meta-data/network/interfaces/macs/12:4d:02:3b:2f:5e/public-ipv4s' with {'url': 'http://169.254.169.254/2016-09-02/meta-data/network/interfaces/macs/12:4d:02:3b:2f:5e/public-ipv4s', 'headers': {'User-Agent': 'Cloud-Init/18.2'}, 'allow_redirects': True, 'method': 'GET', 'timeout': 5.0} configuration
2019-02-12 23:18:15,620 - url_helper.py[DEBUG]: Read from http://169.254.169.254/2016-09-02/meta-data/network/interfaces/macs/12:4d:02:3b:2f:5e/public-ipv4s (200, 13b) after 1 attempts
2019-02-12 23:18:15,620 - url_helper.py[DEBUG]: [0/6] open 'http://169.254.169.254/2016-09-02/meta-data/network/interfaces/macs/12:4d:02:3b:2f:5e/interface-id' with {'url': 'http://169.254.169.254/2016-09-02/meta-data/network/interfaces/macs/12:4d:02:3b:2f:5e/interface-id', 'headers': {'User-Agent': 'Cloud-Init/18.2'}, 'allow_redirects': True, 'method': 'GET', 'timeout': 5.0} configuration
2019-02-12 23:18:15,622 - url_helper.py[DEBUG]: Read from http://169.254.169.254/2016-09-02/meta-data/network/interfaces/macs/12:4d:02:3b:2f:5e/interface-id (200, 21b) after 1 attempts
2019-02-12 23:18:15,622 - url_helper.py[DEBUG]: [0/6] open 'http://169.254.169.254/2016-09-02/meta-data/network/interfaces/macs/12:4d:02:3b:2f:5e/mac' with {'url': 'http://169.254.169.254/2016-09-02/meta-data/network/interfaces/macs/12:4d:02:3b:2f:5e/mac', 'headers': {'User-Agent': 'Cloud-Init/18.2'}, 'allow_redirects': True, 'method': 'GET', 'timeout': 5.0} configuration
2019-02-12 23:18:15,624 - url_helper.py[DEBUG]: Read from http://169.254.169.254/2016-09-02/meta-data/network/interfaces/macs/12:4d:02:3b:2f:5e/mac (200, 17b) after 1 attempts
2019-02-12 23:18:15,625 - url_helper.py[DEBUG]: [0/6] open 'http://169.254.169.254/2016-09-02/meta-data/network/interfaces/macs/12:4d:02:3b:2f:5e/security-group-ids' with {'url': 'http://169.254.169.254/2016-09-02/meta-data/network/interfaces/macs/12:4d:02:3b:2f:5e/security-group-ids', 'headers': {'User-Agent': 'Cloud-Init/18.2'}, 'allow_redirects': True, 'method': 'GET', 'timeout': 5.0} configuration
2019-02-12 23:18:15,627 - url_helper.py[DEBUG]: Read from http://169.254.169.254/2016-09-02/meta-data/network/interfaces/macs/12:4d:02:3b:2f:5e/security-group-ids (200, 20b) after 1 attempts
2019-02-12 23:18:15,627 - url_helper.py[DEBUG]: [0/6] open 'http://169.254.169.254/2016-09-02/meta-data/network/interfaces/macs/12:4d:02:3b:2f:5e/vpc-ipv4-cidr-block' with {'url': 'http://169.254.169.254/2016-09-02/meta-data/network/interfaces/macs/12:4d:02:3b:2f:5e/vpc-ipv4-cidr-block', 'headers': {'User-Agent': 'Cloud-Init/18.2'}, 'allow_redirects': True, 'method': 'GET', 'timeout': 5.0} configuration
2019-02-12 23:18:15,629 - url_helper.py[DEBUG]: Read from http://169.254.169.254/2016-09-02/meta-data/network/interfaces/macs/12:4d:02:3b:2f:5e/vpc-ipv4-cidr-block (200, 13b) after 1 attempts
2019-02-12 23:18:15,629 - url_helper.py[DEBUG]: [0/6] open 'http://169.254.169.254/2016-09-02/meta-data/network/interfaces/macs/12:4d:02:3b:2f:5e/local-ipv4s' with {'url': 'http://169.254.169.254/2016-09-02/meta-data/network/interfaces/macs/12:4d:02:3b:2f:5e/local-ipv4s', 'headers': {'User-Agent': 'Cloud-Init/18.2'}, 'allow_redirects': True, 'method': 'GET', 'timeout': 5.0} configuration
2019-02-12 23:18:15,631 - url_helper.py[DEBUG]: Read from http://169.254.169.254/2016-09-02/meta-data/network/interfaces/macs/12:4d:02:3b:2f:5e/local-ipv4s (200, 13b) after 1 attempts
2019-02-12 23:18:15,632 - url_helper.py[DEBUG]: [0/6] open 'http://169.254.169.254/2016-09-02/meta-data/network/interfaces/macs/12:4d:02:3b:2f:5e/owner-id' with {'url': 'http://169.254.169.254/2016-09-02/meta-data/network/interfaces/macs/12:4d:02:3b:2f:5e/owner-id', 'headers': {'User-Agent': 'Cloud-Init/18.2'}, 'allow_redirects': True, 'method': 'GET', 'timeout': 5.0} configuration
2019-02-12 23:18:15,634 - url_helper.py[DEBUG]: Read from http://169.254.169.254/2016-09-02/meta-data/network/interfaces/macs/12:4d:02:3b:2f:5e/owner-id (200, 12b) after 1 attempts
2019-02-12 23:18:15,634 - url_helper.py[DEBUG]: [0/6] open 'http://169.254.169.254/2016-09-02/meta-data/network/interfaces/macs/12:4d:02:3b:2f:5e/subnet-ipv4-cidr-block' with {'url': 'http://169.254.169.254/2016-09-02/meta-data/network/interfaces/macs/12:4d:02:3b:2f:5e/subnet-ipv4-cidr-block', 'headers': {'User-Agent': 'Cloud-Init/18.2'}, 'allow_redirects': True, 'method': 'GET', 'timeout': 5.0} configuration
2019-02-12 23:18:15,636 - url_helper.py[DEBUG]: Read from http://169.254.169.254/2016-09-02/meta-data/network/interfaces/macs/12:4d:02:3b:2f:5e/subnet-ipv4-cidr-block (200, 14b) after 1 attempts
2019-02-12 23:18:15,636 - url_helper.py[DEBUG]: [0/6] open 'http://169.254.169.254/2016-09-02/meta-data/network/interfaces/macs/12:4d:02:3b:2f:5e/device-number' with {'url': 'http://169.254.169.254/2016-09-02/meta-data/network/interfaces/macs/12:4d:02:3b:2f:5e/device-number', 'headers': {'User-Agent': 'Cloud-Init/18.2'}, 'allow_redirects': True, 'method': 'GET', 'timeout': 5.0} configuration
2019-02-12 23:18:15,638 - url_helper.py[DEBUG]: Read from http://169.254.169.254/2016-09-02/meta-data/network/interfaces/macs/12:4d:02:3b:2f:5e/device-number (200, 1b) after 1 attempts
2019-02-12 23:18:15,639 - url_helper.py[DEBUG]: [0/6] open 'http://169.254.169.254/2016-09-02/meta-data/network/interfaces/macs/12:4d:02:3b:2f:5e/vpc-id' with {'url': 'http://169.254.169.254/2016-09-02/meta-data/network/interfaces/macs/12:4d:02:3b:2f:5e/vpc-id', 'headers': {'User-Agent': 'Cloud-Init/18.2'}, 'allow_redirects': True, 'method': 'GET', 'timeout': 5.0} configuration
2019-02-12 23:18:15,641 - url_helper.py[DEBUG]: Read from http://169.254.169.254/2016-09-02/meta-data/network/interfaces/macs/12:4d:02:3b:2f:5e/vpc-id (200, 12b) after 1 attempts
2019-02-12 23:18:15,641 - url_helper.py[DEBUG]: [0/6] open 'http://169.254.169.254/2016-09-02/meta-data/placement/' with {'url': 'http://169.254.169.254/2016-09-02/meta-data/placement/', 'headers': {'User-Agent': 'Cloud-Init/18.2'}, 'allow_redirects': True, 'method': 'GET', 'timeout': 5.0} configuration
2019-02-12 23:18:15,643 - url_helper.py[DEBUG]: Read from http://169.254.169.254/2016-09-02/meta-data/placement/ (200, 17b) after 1 attempts
2019-02-12 23:18:15,643 - url_helper.py[DEBUG]: [0/6] open 'http://169.254.169.254/2016-09-02/meta-data/placement/availability-zone' with {'url': 'http://169.254.169.254/2016-09-02/meta-data/placement/availability-zone', 'headers': {'User-Agent': 'Cloud-Init/18.2'}, 'allow_redirects': True, 'method': 'GET', 'timeout': 5.0} configuration
2019-02-12 23:18:15,645 - url_helper.py[DEBUG]: Read from http://169.254.169.254/2016-09-02/meta-data/placement/availability-zone (200, 10b) after 1 attempts
2019-02-12 23:18:15,646 - url_helper.py[DEBUG]: [0/6] open 'http://169.254.169.254/2016-09-02/meta-data/public-keys/' with {'url': 'http://169.254.169.254/2016-09-02/meta-data/public-keys/', 'headers': {'User-Agent': 'Cloud-Init/18.2'}, 'allow_redirects': True, 'method': 'GET', 'timeout': 5.0} configuration
2019-02-12 23:18:15,648 - url_helper.py[DEBUG]: Read from http://169.254.169.254/2016-09-02/meta-data/public-keys/ (200, 13b) after 1 attempts
2019-02-12 23:18:15,648 - url_helper.py[DEBUG]: [0/6] open 'http://169.254.169.254/2016-09-02/meta-data/public-keys/0/openssh-key' with {'url': 'http://169.254.169.254/2016-09-02/meta-data/public-keys/0/openssh-key', 'headers': {'User-Agent': 'Cloud-Init/18.2'}, 'allow_redirects': True, 'method': 'GET', 'timeout': 5.0} configuration
2019-02-12 23:18:15,650 - url_helper.py[DEBUG]: Read from http://169.254.169.254/2016-09-02/meta-data/public-keys/0/openssh-key (200, 393b) after 1 attempts
2019-02-12 23:18:15,650 - url_helper.py[DEBUG]: [0/6] open 'http://169.254.169.254/2016-09-02/meta-data/services/' with {'url': 'http://169.254.169.254/2016-09-02/meta-data/services/', 'headers': {'User-Agent': 'Cloud-Init/18.2'}, 'allow_redirects': True, 'method': 'GET', 'timeout': 5.0} configuration
2019-02-12 23:18:15,652 - url_helper.py[DEBUG]: Read from http://169.254.169.254/2016-09-02/meta-data/services/ (200, 16b) after 1 attempts
2019-02-12 23:18:15,653 - url_helper.py[DEBUG]: [0/6] open 'http://169.254.169.254/2016-09-02/meta-data/services/domain' with {'url': 'http://169.254.169.254/2016-09-02/meta-data/services/domain', 'headers': {'User-Agent': 'Cloud-Init/18.2'}, 'allow_redirects': True, 'method': 'GET', 'timeout': 5.0} configuration
2019-02-12 23:18:15,655 - url_helper.py[DEBUG]: Read from http://169.254.169.254/2016-09-02/meta-data/services/domain (200, 13b) after 1 attempts
2019-02-12 23:18:15,655 - url_helper.py[DEBUG]: [0/6] open 'http://169.254.169.254/2016-09-02/meta-data/services/partition' with {'url': 'http://169.254.169.254/2016-09-02/meta-data/services/partition', 'headers': {'User-Agent': 'Cloud-Init/18.2'}, 'allow_redirects': True, 'method': 'GET', 'timeout': 5.0} configuration
2019-02-12 23:18:15,657 - url_helper.py[DEBUG]: Read from http://169.254.169.254/2016-09-02/meta-data/services/partition (200, 3b) after 1 attempts
2019-02-12 23:18:15,657 - url_helper.py[DEBUG]: [0/6] open 'http://169.254.169.254/2016-09-02/meta-data/profile' with {'url': 'http://169.254.169.254/2016-09-02/meta-data/profile', 'headers': {'User-Agent': 'Cloud-Init/18.2'}, 'allow_redirects': True, 'method': 'GET', 'timeout': 5.0} configuration
2019-02-12 23:18:15,659 - url_helper.py[DEBUG]: Read from http://169.254.169.254/2016-09-02/meta-data/profile (200, 11b) after 1 attempts
2019-02-12 23:18:15,660 - url_helper.py[DEBUG]: [0/6] open 'http://169.254.169.254/2016-09-02/meta-data/local-ipv4' with {'url': 'http://169.254.169.254/2016-09-02/meta-data/local-ipv4', 'headers': {'User-Agent': 'Cloud-Init/18.2'}, 'allow_redirects': True, 'method': 'GET', 'timeout': 5.0} configuration
2019-02-12 23:18:15,662 - url_helper.py[DEBUG]: Read from http://169.254.169.254/2016-09-02/meta-data/local-ipv4 (200, 13b) after 1 attempts
2019-02-12 23:18:15,662 - url_helper.py[DEBUG]: [0/6] open 'http://169.254.169.254/2016-09-02/meta-data/reservation-id' with {'url': 'http://169.254.169.254/2016-09-02/meta-data/reservation-id', 'headers': {'User-Agent': 'Cloud-Init/18.2'}, 'allow_redirects': True, 'method': 'GET', 'timeout': 5.0} configuration
2019-02-12 23:18:15,664 - url_helper.py[DEBUG]: Read from http://169.254.169.254/2016-09-02/meta-data/reservation-id (200, 19b) after 1 attempts
2019-02-12 23:18:15,664 - url_helper.py[DEBUG]: [0/6] open 'http://169.254.169.254/2016-09-02/meta-data/local-hostname' with {'url': 'http://169.254.169.254/2016-09-02/meta-data/local-hostname', 'headers': {'User-Agent': 'Cloud-Init/18.2'}, 'allow_redirects': True, 'method': 'GET', 'timeout': 5.0} configuration
2019-02-12 23:18:15,666 - url_helper.py[DEBUG]: Read from http://169.254.169.254/2016-09-02/meta-data/local-hostname (200, 29b) after 1 attempts
2019-02-12 23:18:15,666 - url_helper.py[DEBUG]: [0/6] open 'http://169.254.169.254/2016-09-02/meta-data/security-groups' with {'url': 'http://169.254.169.254/2016-09-02/meta-data/security-groups', 'headers': {'User-Agent': 'Cloud-Init/18.2'}, 'allow_redirects': True, 'method': 'GET', 'timeout': 5.0} configuration
2019-02-12 23:18:15,669 - url_helper.py[DEBUG]: Read from http://169.254.169.254/2016-09-02/meta-data/security-groups (200, 61b) after 1 attempts
2019-02-12 23:18:15,669 - url_helper.py[DEBUG]: [0/6] open 'http://169.254.169.254/2016-09-02/meta-data/product-codes' with {'url': 'http://169.254.169.254/2016-09-02/meta-data/product-codes', 'headers': {'User-Agent': 'Cloud-Init/18.2'}, 'allow_redirects': True, 'method': 'GET', 'timeout': 5.0} configuration
2019-02-12 23:18:15,671 - url_helper.py[DEBUG]: Read from http://169.254.169.254/2016-09-02/meta-data/product-codes (200, 25b) after 1 attempts
2019-02-12 23:18:15,671 - url_helper.py[DEBUG]: [0/6] open 'http://169.254.169.254/2016-09-02/meta-data/ami-launch-index' with {'url': 'http://169.254.169.254/2016-09-02/meta-data/ami-launch-index', 'headers': {'User-Agent': 'Cloud-Init/18.2'}, 'allow_redirects': True, 'method': 'GET', 'timeout': 5.0} configuration
2019-02-12 23:18:15,673 - url_helper.py[DEBUG]: Read from http://169.254.169.254/2016-09-02/meta-data/ami-launch-index (200, 1b) after 1 attempts
2019-02-12 23:18:15,673 - url_helper.py[DEBUG]: [0/6] open 'http://169.254.169.254/2016-09-02/meta-data/public-hostname' with {'url': 'http://169.254.169.254/2016-09-02/meta-data/public-hostname', 'headers': {'User-Agent': 'Cloud-Init/18.2'}, 'allow_redirects': True, 'method': 'GET', 'timeout': 5.0} configuration
2019-02-12 23:18:15,676 - url_helper.py[DEBUG]: Read from http://169.254.169.254/2016-09-02/meta-data/public-hostname (200, 41b) after 1 attempts
2019-02-12 23:18:15,676 - url_helper.py[DEBUG]: [0/6] open 'http://169.254.169.254/2016-09-02/meta-data/hostname' with {'url': 'http://169.254.169.254/2016-09-02/meta-data/hostname', 'headers': {'User-Agent': 'Cloud-Init/18.2'}, 'allow_redirects': True, 'method': 'GET', 'timeout': 5.0} configuration
2019-02-12 23:18:15,678 - url_helper.py[DEBUG]: Read from http://169.254.169.254/2016-09-02/meta-data/hostname (200, 29b) after 1 attempts
2019-02-12 23:18:15,678 - url_helper.py[DEBUG]: [0/6] open 'http://169.254.169.254/2016-09-02/meta-data/ami-id' with {'url': 'http://169.254.169.254/2016-09-02/meta-data/ami-id', 'headers': {'User-Agent': 'Cloud-Init/18.2'}, 'allow_redirects': True, 'method': 'GET', 'timeout': 5.0} configuration
2019-02-12 23:18:15,680 - url_helper.py[DEBUG]: Read from http://169.254.169.254/2016-09-02/meta-data/ami-id (200, 21b) after 1 attempts
2019-02-12 23:18:15,680 - url_helper.py[DEBUG]: [0/6] open 'http://169.254.169.254/2016-09-02/meta-data/instance-action' with {'url': 'http://169.254.169.254/2016-09-02/meta-data/instance-action', 'headers': {'User-Agent': 'Cloud-Init/18.2'}, 'allow_redirects': True, 'method': 'GET', 'timeout': 5.0} configuration
2019-02-12 23:18:15,682 - url_helper.py[DEBUG]: Read from http://169.254.169.254/2016-09-02/meta-data/instance-action (200, 4b) after 1 attempts
2019-02-12 23:18:15,683 - url_helper.py[DEBUG]: [0/6] open 'http://169.254.169.254/2016-09-02/meta-data/mac' with {'url': 'http://169.254.169.254/2016-09-02/meta-data/mac', 'headers': {'User-Agent': 'Cloud-Init/18.2'}, 'allow_redirects': True, 'method': 'GET', 'timeout': 5.0} configuration
2019-02-12 23:18:15,685 - url_helper.py[DEBUG]: Read from http://169.254.169.254/2016-09-02/meta-data/mac (200, 17b) after 1 attempts
2019-02-12 23:18:15,685 - url_helper.py[DEBUG]: [0/6] open 'http://169.254.169.254/2016-09-02/meta-data/public-ipv4' with {'url': 'http://169.254.169.254/2016-09-02/meta-data/public-ipv4', 'headers': {'User-Agent': 'Cloud-Init/18.2'}, 'allow_redirects': True, 'method': 'GET', 'timeout': 5.0} configuration
2019-02-12 23:18:15,687 - url_helper.py[DEBUG]: Read from http://169.254.169.254/2016-09-02/meta-data/public-ipv4 (200, 13b) after 1 attempts
2019-02-12 23:18:15,687 - url_helper.py[DEBUG]: [0/6] open 'http://169.254.169.254/2016-09-02/meta-data/ami-manifest-path' with {'url': 'http://169.254.169.254/2016-09-02/meta-data/ami-manifest-path', 'headers': {'User-Agent': 'Cloud-Init/18.2'}, 'allow_redirects': True, 'method': 'GET', 'timeout': 5.0} configuration
2019-02-12 23:18:15,690 - url_helper.py[DEBUG]: Read from http://169.254.169.254/2016-09-02/meta-data/ami-manifest-path (200, 9b) after 1 attempts
2019-02-12 23:18:15,690 - url_helper.py[DEBUG]: [0/6] open 'http://169.254.169.254/2016-09-02/meta-data/instance-type' with {'url': 'http://169.254.169.254/2016-09-02/meta-data/instance-type', 'headers': {'User-Agent': 'Cloud-Init/18.2'}, 'allow_redirects': True, 'method': 'GET', 'timeout': 5.0} configuration
2019-02-12 23:18:15,692 - url_helper.py[DEBUG]: Read from http://169.254.169.254/2016-09-02/meta-data/instance-type (200, 8b) after 1 attempts
2019-02-12 23:18:15,692 - url_helper.py[DEBUG]: [0/6] open 'http://169.254.169.254/2016-09-02/meta-data/instance-id' with {'url': 'http://169.254.169.254/2016-09-02/meta-data/instance-id', 'headers': {'User-Agent': 'Cloud-Init/18.2'}, 'allow_redirects': True, 'method': 'GET', 'timeout': 5.0} configuration
2019-02-12 23:18:15,694 - url_helper.py[DEBUG]: Read from http://169.254.169.254/2016-09-02/meta-data/instance-id (200, 19b) after 1 attempts
2019-02-12 23:18:15,694 - url_helper.py[DEBUG]: [0/6] open 'http://169.254.169.254/2016-09-02/dynamic/instance-identity' with {'url': 'http://169.254.169.254/2016-09-02/dynamic/instance-identity', 'headers': {'User-Agent': 'Cloud-Init/18.2'}, 'allow_redirects': True, 'method': 'GET', 'timeout': 5.0} configuration
2019-02-12 23:18:15,698 - url_helper.py[DEBUG]: Read from http://169.254.169.254/2016-09-02/dynamic/instance-identity (200, 33b) after 1 attempts
2019-02-12 23:18:15,698 - url_helper.py[DEBUG]: [0/6] open 'http://169.254.169.254/2016-09-02/dynamic/instance-identity/document' with {'url': 'http://169.254.169.254/2016-09-02/dynamic/instance-identity/document', 'headers': {'User-Agent': 'Cloud-Init/18.2'}, 'allow_redirects': True, 'method': 'GET', 'timeout': 5.0} configuration
2019-02-12 23:18:15,700 - url_helper.py[DEBUG]: Read from http://169.254.169.254/2016-09-02/dynamic/instance-identity/document (200, 504b) after 1 attempts
2019-02-12 23:18:15,700 - url_helper.py[DEBUG]: [0/6] open 'http://169.254.169.254/2016-09-02/dynamic/instance-identity/signature' with {'url': 'http://169.254.169.254/2016-09-02/dynamic/instance-identity/signature', 'headers': {'User-Agent': 'Cloud-Init/18.2'}, 'allow_redirects': True, 'method': 'GET', 'timeout': 5.0} configuration
2019-02-12 23:18:15,702 - url_helper.py[DEBUG]: Read from http://169.254.169.254/2016-09-02/dynamic/instance-identity/signature (200, 174b) after 1 attempts
2019-02-12 23:18:15,703 - url_helper.py[DEBUG]: [0/6] open 'http://169.254.169.254/2016-09-02/dynamic/instance-identity/pkcs7' with {'url': 'http://169.254.169.254/2016-09-02/dynamic/instance-identity/pkcs7', 'headers': {'User-Agent': 'Cloud-Init/18.2'}, 'allow_redirects': True, 'method': 'GET', 'timeout': 5.0} configuration
2019-02-12 23:18:15,705 - url_helper.py[DEBUG]: Read from http://169.254.169.254/2016-09-02/dynamic/instance-identity/pkcs7 (200, 1154b) after 1 attempts
2019-02-12 23:18:15,705 - url_helper.py[DEBUG]: [0/6] open 'http://169.254.169.254/2016-09-02/dynamic/instance-identity/rsa2048' with {'url': 'http://169.254.169.254/2016-09-02/dynamic/instance-identity/rsa2048', 'headers': {'User-Agent': 'Cloud-Init/18.2'}, 'allow_redirects': True, 'method': 'GET', 'timeout': 5.0} configuration
2019-02-12 23:18:15,707 - url_helper.py[DEBUG]: Read from http://169.254.169.254/2016-09-02/dynamic/instance-identity/rsa2048 (200, 1471b) after 1 attempts
2019-02-12 23:18:15,707 - util.py[DEBUG]: Crawl of metadata service took 50.214 seconds
2019-02-12 23:18:15,707 - util.py[DEBUG]: Running command ['ip', '-4', 'route', 'del', 'default', 'dev', 'eth0'] with allowed return codes [0] (shell=False, capture=True)
2019-02-12 23:18:15,710 - util.py[DEBUG]: Running command ['ip', '-family', 'inet', 'link', 'set', 'dev', 'eth0', 'down'] with allowed return codes [0] (shell=False, capture=True)
2019-02-12 23:18:15,713 - util.py[DEBUG]: Running command ['ip', '-family', 'inet', 'addr', 'del', '172.31.84.133/20', 'dev', 'eth0'] with allowed return codes [0] (shell=False, capture=True)
2019-02-12 23:18:15,717 - handlers.py[DEBUG]: finish: init-local/search-Ec2Local: SUCCESS: found local data from DataSourceEc2Local
2019-02-12 23:18:15,717 - stages.py[INFO]: Loaded datasource DataSourceEc2Local - DataSourceEc2Local
2019-02-12 23:18:15,718 - util.py[DEBUG]: Reading from /etc/cloud/cloud.cfg (quiet=False)
2019-02-12 23:18:15,718 - util.py[DEBUG]: Read 1198 bytes from /etc/cloud/cloud.cfg
2019-02-12 23:18:15,718 - util.py[DEBUG]: Attempting to load yaml from string of length 1198 with allowed root types (<type 'dict'>,)
2019-02-12 23:18:15,727 - util.py[DEBUG]: Reading from /etc/cloud/cloud.cfg.d/05_logging.cfg (quiet=False)
2019-02-12 23:18:15,727 - util.py[DEBUG]: Read 1821 bytes from /etc/cloud/cloud.cfg.d/05_logging.cfg
2019-02-12 23:18:15,727 - util.py[DEBUG]: Attempting to load yaml from string of length 1821 with allowed root types (<type 'dict'>,)
2019-02-12 23:18:15,730 - util.py[DEBUG]: Reading from /run/cloud-init/cloud.cfg (quiet=False)
2019-02-12 23:18:15,731 - util.py[DEBUG]: Attempting to load yaml from string of length 0 with allowed root types (<type 'dict'>,)
2019-02-12 23:18:15,731 - util.py[DEBUG]: loaded blob returned None, returning default.
2019-02-12 23:18:15,731 - util.py[DEBUG]: Attempting to remove /var/lib/cloud/instance
2019-02-12 23:18:15,731 - util.py[DEBUG]: Creating symbolic link from '/var/lib/cloud/instance' => '/var/lib/cloud/instances/i-0cd230a0ccdebe749'
2019-02-12 23:18:15,732 - util.py[DEBUG]: Restoring selinux mode for /var/lib/cloud/instances/i-0cd230a0ccdebe749 (recursive=True)
2019-02-12 23:18:15,733 - util.py[DEBUG]: Restoring selinux mode for /var/lib/cloud/instances/i-0cd230a0ccdebe749/handlers (recursive=False)
2019-02-12 23:18:15,734 - util.py[DEBUG]: Restoring selinux mode for /var/lib/cloud/instances/i-0cd230a0ccdebe749 (recursive=True)
2019-02-12 23:18:15,735 - util.py[DEBUG]: Restoring selinux mode for /var/lib/cloud/instances/i-0cd230a0ccdebe749/scripts (recursive=False)
2019-02-12 23:18:15,735 - util.py[DEBUG]: Restoring selinux mode for /var/lib/cloud/instances/i-0cd230a0ccdebe749 (recursive=True)
2019-02-12 23:18:15,736 - util.py[DEBUG]: Restoring selinux mode for /var/lib/cloud/instances/i-0cd230a0ccdebe749/sem (recursive=False)
2019-02-12 23:18:15,736 - util.py[DEBUG]: Reading from /var/lib/cloud/instances/i-0cd230a0ccdebe749/datasource (quiet=False)
2019-02-12 23:18:15,736 - util.py[DEBUG]: Writing to /var/lib/cloud/instances/i-0cd230a0ccdebe749/datasource - wb: [644] 39 bytes
2019-02-12 23:18:15,737 - util.py[DEBUG]: Restoring selinux mode for /var/lib/cloud/instances/i-0cd230a0ccdebe749/datasource (recursive=False)
2019-02-12 23:18:15,737 - util.py[DEBUG]: Restoring selinux mode for /var/lib/cloud/instances/i-0cd230a0ccdebe749/datasource (recursive=False)
2019-02-12 23:18:15,738 - util.py[DEBUG]: Writing to /var/lib/cloud/data/previous-datasource - wb: [644] 39 bytes
2019-02-12 23:18:15,738 - util.py[DEBUG]: Restoring selinux mode for /var/lib/cloud/data/previous-datasource (recursive=False)
2019-02-12 23:18:15,739 - util.py[DEBUG]: Restoring selinux mode for /var/lib/cloud/data/previous-datasource (recursive=False)
2019-02-12 23:18:15,739 - util.py[DEBUG]: Reading from /var/lib/cloud/data/instance-id (quiet=False)
2019-02-12 23:18:15,739 - stages.py[DEBUG]: previous iid found to be NO_PREVIOUS_INSTANCE_ID
2019-02-12 23:18:15,739 - util.py[DEBUG]: Writing to /var/lib/cloud/data/instance-id - wb: [644] 20 bytes
2019-02-12 23:18:15,739 - util.py[DEBUG]: Restoring selinux mode for /var/lib/cloud/data/instance-id (recursive=False)
2019-02-12 23:18:15,740 - util.py[DEBUG]: Restoring selinux mode for /var/lib/cloud/data/instance-id (recursive=False)
2019-02-12 23:18:15,740 - util.py[DEBUG]: Writing to /run/cloud-init/.instance-id - wb: [644] 20 bytes
2019-02-12 23:18:15,741 - util.py[DEBUG]: Restoring selinux mode for /run/cloud-init/.instance-id (recursive=False)
2019-02-12 23:18:15,741 - util.py[DEBUG]: Restoring selinux mode for /run/cloud-init/.instance-id (recursive=False)
2019-02-12 23:18:15,742 - util.py[DEBUG]: Writing to /var/lib/cloud/data/previous-instance-id - wb: [644] 24 bytes
2019-02-12 23:18:15,742 - util.py[DEBUG]: Restoring selinux mode for /var/lib/cloud/data/previous-instance-id (recursive=False)
2019-02-12 23:18:15,742 - util.py[DEBUG]: Restoring selinux mode for /var/lib/cloud/data/previous-instance-id (recursive=False)
2019-02-12 23:18:15,743 - util.py[DEBUG]: Writing to /var/lib/cloud/instance/obj.pkl - wb: [400] 8079 bytes
2019-02-12 23:18:15,744 - util.py[DEBUG]: Restoring selinux mode for /var/lib/cloud/instances/i-0cd230a0ccdebe749/obj.pkl (recursive=False)
2019-02-12 23:18:15,744 - util.py[DEBUG]: Restoring selinux mode for /var/lib/cloud/instances/i-0cd230a0ccdebe749/obj.pkl (recursive=False)
2019-02-12 23:18:15,745 - main.py[DEBUG]: [local] init will now be targeting instance id: i-0cd230a0ccdebe749. new=True
2019-02-12 23:18:15,745 - util.py[DEBUG]: Reading from /etc/cloud/cloud.cfg (quiet=False)
2019-02-12 23:18:15,745 - util.py[DEBUG]: Read 1198 bytes from /etc/cloud/cloud.cfg
2019-02-12 23:18:15,745 - util.py[DEBUG]: Attempting to load yaml from string of length 1198 with allowed root types (<type 'dict'>,)
2019-02-12 23:18:15,753 - util.py[DEBUG]: Reading from /etc/cloud/cloud.cfg.d/05_logging.cfg (quiet=False)
2019-02-12 23:18:15,753 - util.py[DEBUG]: Read 1821 bytes from /etc/cloud/cloud.cfg.d/05_logging.cfg
2019-02-12 23:18:15,754 - util.py[DEBUG]: Attempting to load yaml from string of length 1821 with allowed root types (<type 'dict'>,)
2019-02-12 23:18:15,757 - util.py[DEBUG]: Reading from /run/cloud-init/cloud.cfg (quiet=False)
2019-02-12 23:18:15,757 - util.py[DEBUG]: Attempting to load yaml from string of length 0 with allowed root types (<type 'dict'>,)
2019-02-12 23:18:15,758 - util.py[DEBUG]: loaded blob returned None, returning default.
2019-02-12 23:18:15,759 - stages.py[DEBUG]: Using distro class <class 'cloudinit.distros.rhel.Distro'>
2019-02-12 23:18:15,759 - cc_set_hostname.py[DEBUG]: Setting the hostname to ip-172-31-84-133.ec2.internal (ip-172-31-84-133)
2019-02-12 23:18:15,760 - util.py[DEBUG]: Running command ['hostnamectl', 'set-hostname', 'ip-172-31-84-133.ec2.internal'] with allowed return codes [0] (shell=False, capture=True)
2019-02-12 23:18:15,819 - __init__.py[DEBUG]: Non-persistently setting the system hostname to ip-172-31-84-133.ec2.internal
2019-02-12 23:18:15,819 - util.py[DEBUG]: Running command ['hostname', 'ip-172-31-84-133.ec2.internal'] with allowed return codes [0] (shell=False, capture=True)
2019-02-12 23:18:15,829 - util.py[DEBUG]: Reading from /sys/class/net/eth0/address (quiet=False)
2019-02-12 23:18:15,829 - util.py[DEBUG]: Read 18 bytes from /sys/class/net/eth0/address
2019-02-12 23:18:15,829 - stages.py[DEBUG]: applying net config names for {'version': 1, 'config': [{'subnets': [{'type': 'dhcp4'}], 'type': 'physical', 'name': 'eth0', 'mac_address': '12:4d:02:3b:2f:5e'}]}
2019-02-12 23:18:15,829 - util.py[DEBUG]: Reading from /sys/class/net/eth0/device/device (quiet=False)
2019-02-12 23:18:15,830 - util.py[DEBUG]: Reading from /sys/class/net/eth0/addr_assign_type (quiet=False)
2019-02-12 23:18:15,830 - util.py[DEBUG]: Read 2 bytes from /sys/class/net/eth0/addr_assign_type
2019-02-12 23:18:15,830 - util.py[DEBUG]: Reading from /sys/class/net/eth0/uevent (quiet=False)
2019-02-12 23:18:15,830 - util.py[DEBUG]: Read 25 bytes from /sys/class/net/eth0/uevent
2019-02-12 23:18:15,830 - util.py[DEBUG]: Reading from /sys/class/net/eth0/address (quiet=False)
2019-02-12 23:18:15,830 - util.py[DEBUG]: Read 18 bytes from /sys/class/net/eth0/address
2019-02-12 23:18:15,830 - util.py[DEBUG]: Reading from /sys/class/net/eth0/device/device (quiet=False)
2019-02-12 23:18:15,830 - util.py[DEBUG]: Reading from /sys/class/net/lo/addr_assign_type (quiet=False)
2019-02-12 23:18:15,830 - util.py[DEBUG]: Read 2 bytes from /sys/class/net/lo/addr_assign_type
2019-02-12 23:18:15,830 - util.py[DEBUG]: Reading from /sys/class/net/lo/uevent (quiet=False)
2019-02-12 23:18:15,831 - util.py[DEBUG]: Read 23 bytes from /sys/class/net/lo/uevent
2019-02-12 23:18:15,831 - util.py[DEBUG]: Reading from /sys/class/net/lo/address (quiet=False)
2019-02-12 23:18:15,831 - util.py[DEBUG]: Read 18 bytes from /sys/class/net/lo/address
2019-02-12 23:18:15,831 - util.py[DEBUG]: Reading from /sys/class/net/lo/device/device (quiet=False)
2019-02-12 23:18:15,831 - util.py[DEBUG]: Reading from /sys/class/net/eth0/operstate (quiet=False)
2019-02-12 23:18:15,831 - util.py[DEBUG]: Read 5 bytes from /sys/class/net/eth0/operstate
2019-02-12 23:18:15,831 - util.py[DEBUG]: Reading from /sys/class/net/lo/operstate (quiet=False)
2019-02-12 23:18:15,832 - util.py[DEBUG]: Read 8 bytes from /sys/class/net/lo/operstate
2019-02-12 23:18:15,833 - util.py[DEBUG]: Running command ['ip', '-6', 'addr', 'show', 'permanent', 'scope', 'global'] with allowed return codes [0] (shell=False, capture=True)
2019-02-12 23:18:15,837 - util.py[DEBUG]: Running command ['ip', '-4', 'addr', 'show'] with allowed return codes [0] (shell=False, capture=True)
2019-02-12 23:18:15,840 - __init__.py[DEBUG]: no work necessary for renaming of [['12:4d:02:3b:2f:5e', 'eth0', 'vif', None]]
2019-02-12 23:18:15,840 - stages.py[INFO]: Applying network configuration from ds bringup=False: {'version': 1, 'config': [{'subnets': [{'type': 'dhcp4'}], 'type': 'physical', 'name': 'eth0', 'mac_address': '12:4d:02:3b:2f:5e'}]}
2019-02-12 23:18:15,840 - __init__.py[DEBUG]: Selected renderer 'sysconfig' from priority list: None
2019-02-12 23:18:15,844 - util.py[DEBUG]: Writing to /etc/sysconfig/network-scripts/ifcfg-eth0 - wb: [644] 159 bytes
2019-02-12 23:18:15,844 - util.py[DEBUG]: Restoring selinux mode for /etc/sysconfig/network-scripts/ifcfg-eth0 (recursive=False)
2019-02-12 23:18:15,845 - util.py[DEBUG]: Restoring selinux mode for /etc/sysconfig/network-scripts/ifcfg-eth0 (recursive=False)
2019-02-12 23:18:15,845 - util.py[DEBUG]: Reading from /etc/resolv.conf (quiet=False)
2019-02-12 23:18:15,845 - util.py[DEBUG]: Read 50 bytes from /etc/resolv.conf
2019-02-12 23:18:15,845 - util.py[DEBUG]: Writing to /etc/resolv.conf - wb: [644] 121 bytes
2019-02-12 23:18:15,846 - util.py[DEBUG]: Restoring selinux mode for /etc/resolv.conf (recursive=False)
2019-02-12 23:18:15,846 - util.py[DEBUG]: Restoring selinux mode for /etc/resolv.conf (recursive=False)
2019-02-12 23:18:15,846 - util.py[DEBUG]: Writing to /etc/udev/rules.d/70-persistent-net.rules - wb: [644] 96 bytes
2019-02-12 23:18:15,847 - util.py[DEBUG]: Restoring selinux mode for /etc/udev/rules.d/70-persistent-net.rules (recursive=False)
2019-02-12 23:18:15,847 - util.py[DEBUG]: Restoring selinux mode for /etc/udev/rules.d/70-persistent-net.rules (recursive=False)
2019-02-12 23:18:15,847 - util.py[DEBUG]: Writing to /etc/sysconfig/network - wb: [644] 86 bytes
2019-02-12 23:18:15,848 - util.py[DEBUG]: Restoring selinux mode for /etc/sysconfig/network (recursive=False)
2019-02-12 23:18:15,848 - util.py[DEBUG]: Restoring selinux mode for /etc/sysconfig/network (recursive=False)
2019-02-12 23:18:15,848 - main.py[DEBUG]: [local] Exiting. datasource DataSourceEc2Local not in local mode.
2019-02-12 23:18:15,849 - util.py[DEBUG]: Reading from /proc/uptime (quiet=False)
2019-02-12 23:18:15,849 - util.py[DEBUG]: Read 12 bytes from /proc/uptime
2019-02-12 23:18:15,849 - util.py[DEBUG]: cloud-init mode 'init' took 50.669 seconds (50.67)
2019-02-12 23:18:15,849 - handlers.py[DEBUG]: finish: init-local: SUCCESS: searching for local datasources
2019-02-12 23:18:18,991 - util.py[DEBUG]: Cloud-init v. 18.2 running 'init' at Tue, 12 Feb 2019 23:18:18 +0000. Up 62.09 seconds.
2019-02-12 23:18:18,991 - main.py[DEBUG]: No kernel command line url found.
2019-02-12 23:18:18,991 - main.py[DEBUG]: Closing stdin.
2019-02-12 23:18:18,992 - util.py[DEBUG]: Restoring selinux mode for /var/lib/cloud (recursive=False)
2019-02-12 23:18:18,992 - util.py[DEBUG]: Restoring selinux mode for /var/lib/cloud/scripts (recursive=False)
2019-02-12 23:18:18,993 - util.py[DEBUG]: Restoring selinux mode for /var/lib/cloud/scripts/per-instance (recursive=False)
2019-02-12 23:18:18,993 - util.py[DEBUG]: Restoring selinux mode for /var/lib/cloud/scripts/per-once (recursive=False)
2019-02-12 23:18:18,994 - util.py[DEBUG]: Restoring selinux mode for /var/lib/cloud/scripts/per-boot (recursive=False)
2019-02-12 23:18:18,994 - util.py[DEBUG]: Restoring selinux mode for /var/lib/cloud/scripts/vendor (recursive=False)
2019-02-12 23:18:18,994 - util.py[DEBUG]: Restoring selinux mode for /var/lib/cloud/seed (recursive=False)
2019-02-12 23:18:18,995 - util.py[DEBUG]: Restoring selinux mode for /var/lib/cloud/instances (recursive=False)
2019-02-12 23:18:19,010 - util.py[DEBUG]: Restoring selinux mode for /var/lib/cloud/handlers (recursive=False)
2019-02-12 23:18:19,011 - util.py[DEBUG]: Restoring selinux mode for /var/lib/cloud/sem (recursive=False)
2019-02-12 23:18:19,011 - util.py[DEBUG]: Restoring selinux mode for /var/lib/cloud/data (recursive=False)
2019-02-12 23:18:19,012 - util.py[DEBUG]: Writing to /var/log/cloud-init.log - ab: [600] 0 bytes
2019-02-12 23:18:19,012 - util.py[DEBUG]: Restoring selinux mode for /var/log/cloud-init.log (recursive=False)
2019-02-12 23:18:19,013 - util.py[DEBUG]: Restoring selinux mode for /var/log/cloud-init.log (recursive=False)
2019-02-12 23:18:19,013 - util.py[DEBUG]: Running command ['ifconfig', '-a'] with allowed return codes [0, 1] (shell=False, capture=True)
2019-02-12 23:18:19,038 - util.py[DEBUG]: Running command ['netstat', '-rn'] with allowed return codes [0, 1] (shell=False, capture=True)
2019-02-12 23:18:19,051 - util.py[DEBUG]: Running command ['netstat', '-A', 'inet6', '-n'] with allowed return codes [0, 1] (shell=False, capture=True)
2019-02-12 23:18:19,055 - main.py[DEBUG]: Checking to see if files that we need already exist from a previous run that would allow us to stop early.
2019-02-12 23:18:19,055 - main.py[DEBUG]: Execution continuing, no previous run detected that would allow us to stop early.
2019-02-12 23:18:19,055 - handlers.py[DEBUG]: start: init-network/check-cache: attempting to read from cache [trust]
2019-02-12 23:18:19,055 - util.py[DEBUG]: Reading from /var/lib/cloud/instance/obj.pkl (quiet=False)
2019-02-12 23:18:19,055 - util.py[DEBUG]: Read 8079 bytes from /var/lib/cloud/instance/obj.pkl
2019-02-12 23:18:19,058 - util.py[DEBUG]: Reading from /run/cloud-init/.instance-id (quiet=False)
2019-02-12 23:18:19,059 - util.py[DEBUG]: Read 20 bytes from /run/cloud-init/.instance-id
2019-02-12 23:18:19,059 - stages.py[DEBUG]: restored from cache with run check: DataSourceEc2Local
2019-02-12 23:18:19,059 - handlers.py[DEBUG]: finish: init-network/check-cache: SUCCESS: restored from cache with run check: DataSourceEc2Local
2019-02-12 23:18:19,059 - util.py[DEBUG]: Reading from /etc/cloud/cloud.cfg (quiet=False)
2019-02-12 23:18:19,059 - util.py[DEBUG]: Read 1198 bytes from /etc/cloud/cloud.cfg
2019-02-12 23:18:19,059 - util.py[DEBUG]: Attempting to load yaml from string of length 1198 with allowed root types (<type 'dict'>,)
2019-02-12 23:18:19,100 - util.py[DEBUG]: Reading from /etc/cloud/cloud.cfg.d/05_logging.cfg (quiet=False)
2019-02-12 23:18:19,100 - util.py[DEBUG]: Read 1821 bytes from /etc/cloud/cloud.cfg.d/05_logging.cfg
2019-02-12 23:18:19,100 - util.py[DEBUG]: Attempting to load yaml from string of length 1821 with allowed root types (<type 'dict'>,)
2019-02-12 23:18:19,104 - util.py[DEBUG]: Reading from /run/cloud-init/cloud.cfg (quiet=False)
2019-02-12 23:18:19,104 - util.py[DEBUG]: Attempting to load yaml from string of length 0 with allowed root types (<type 'dict'>,)
2019-02-12 23:18:19,104 - util.py[DEBUG]: loaded blob returned None, returning default.
2019-02-12 23:18:19,105 - util.py[DEBUG]: Attempting to remove /var/lib/cloud/instance
2019-02-12 23:18:19,105 - util.py[DEBUG]: Creating symbolic link from '/var/lib/cloud/instance' => '/var/lib/cloud/instances/i-0cd230a0ccdebe749'
2019-02-12 23:18:19,105 - util.py[DEBUG]: Restoring selinux mode for /var/lib/cloud/instances/i-0cd230a0ccdebe749/handlers (recursive=False)
2019-02-12 23:18:19,106 - util.py[DEBUG]: Restoring selinux mode for /var/lib/cloud/instances/i-0cd230a0ccdebe749/scripts (recursive=False)
2019-02-12 23:18:19,106 - util.py[DEBUG]: Restoring selinux mode for /var/lib/cloud/instances/i-0cd230a0ccdebe749/sem (recursive=False)
2019-02-12 23:18:19,106 - util.py[DEBUG]: Reading from /var/lib/cloud/instances/i-0cd230a0ccdebe749/datasource (quiet=False)
2019-02-12 23:18:19,107 - util.py[DEBUG]: Read 39 bytes from /var/lib/cloud/instances/i-0cd230a0ccdebe749/datasource
2019-02-12 23:18:19,107 - util.py[DEBUG]: Writing to /var/lib/cloud/instances/i-0cd230a0ccdebe749/datasource - wb: [644] 39 bytes
2019-02-12 23:18:19,127 - util.py[DEBUG]: Restoring selinux mode for /var/lib/cloud/instances/i-0cd230a0ccdebe749/datasource (recursive=False)
2019-02-12 23:18:19,127 - util.py[DEBUG]: Restoring selinux mode for /var/lib/cloud/instances/i-0cd230a0ccdebe749/datasource (recursive=False)
2019-02-12 23:18:19,128 - util.py[DEBUG]: Writing to /var/lib/cloud/data/previous-datasource - wb: [644] 39 bytes
2019-02-12 23:18:19,128 - util.py[DEBUG]: Restoring selinux mode for /var/lib/cloud/data/previous-datasource (recursive=False)
2019-02-12 23:18:19,129 - util.py[DEBUG]: Restoring selinux mode for /var/lib/cloud/data/previous-datasource (recursive=False)
2019-02-12 23:18:19,129 - util.py[DEBUG]: Reading from /var/lib/cloud/data/instance-id (quiet=False)
2019-02-12 23:18:19,129 - util.py[DEBUG]: Read 20 bytes from /var/lib/cloud/data/instance-id
2019-02-12 23:18:19,129 - stages.py[DEBUG]: previous iid found to be i-0cd230a0ccdebe749
2019-02-12 23:18:19,129 - util.py[DEBUG]: Writing to /var/lib/cloud/data/instance-id - wb: [644] 20 bytes
2019-02-12 23:18:19,129 - util.py[DEBUG]: Restoring selinux mode for /var/lib/cloud/data/instance-id (recursive=False)
2019-02-12 23:18:19,130 - util.py[DEBUG]: Restoring selinux mode for /var/lib/cloud/data/instance-id (recursive=False)
2019-02-12 23:18:19,130 - util.py[DEBUG]: Writing to /run/cloud-init/.instance-id - wb: [644] 20 bytes
2019-02-12 23:18:19,131 - util.py[DEBUG]: Restoring selinux mode for /run/cloud-init/.instance-id (recursive=False)
2019-02-12 23:18:19,131 - util.py[DEBUG]: Restoring selinux mode for /run/cloud-init/.instance-id (recursive=False)
2019-02-12 23:18:19,132 - util.py[DEBUG]: Writing to /var/lib/cloud/data/previous-instance-id - wb: [644] 20 bytes
2019-02-12 23:18:19,132 - util.py[DEBUG]: Restoring selinux mode for /var/lib/cloud/data/previous-instance-id (recursive=False)
2019-02-12 23:18:19,132 - util.py[DEBUG]: Restoring selinux mode for /var/lib/cloud/data/previous-instance-id (recursive=False)
2019-02-12 23:18:19,133 - util.py[DEBUG]: Writing to /var/lib/cloud/instance/obj.pkl - wb: [400] 8141 bytes
2019-02-12 23:18:19,134 - util.py[DEBUG]: Restoring selinux mode for /var/lib/cloud/instances/i-0cd230a0ccdebe749/obj.pkl (recursive=False)
2019-02-12 23:18:19,134 - util.py[DEBUG]: Restoring selinux mode for /var/lib/cloud/instances/i-0cd230a0ccdebe749/obj.pkl (recursive=False)
2019-02-12 23:18:19,135 - main.py[DEBUG]: [net] init will now be targeting instance id: i-0cd230a0ccdebe749. new=False
2019-02-12 23:18:19,135 - util.py[DEBUG]: Reading from /etc/cloud/cloud.cfg (quiet=False)
2019-02-12 23:18:19,135 - util.py[DEBUG]: Read 1198 bytes from /etc/cloud/cloud.cfg
2019-02-12 23:18:19,135 - util.py[DEBUG]: Attempting to load yaml from string of length 1198 with allowed root types (<type 'dict'>,)
2019-02-12 23:18:19,143 - util.py[DEBUG]: Reading from /etc/cloud/cloud.cfg.d/05_logging.cfg (quiet=False)
2019-02-12 23:18:19,143 - util.py[DEBUG]: Read 1821 bytes from /etc/cloud/cloud.cfg.d/05_logging.cfg
2019-02-12 23:18:19,143 - util.py[DEBUG]: Attempting to load yaml from string of length 1821 with allowed root types (<type 'dict'>,)
2019-02-12 23:18:19,147 - util.py[DEBUG]: Reading from /run/cloud-init/cloud.cfg (quiet=False)
2019-02-12 23:18:19,147 - util.py[DEBUG]: Attempting to load yaml from string of length 0 with allowed root types (<type 'dict'>,)
2019-02-12 23:18:19,147 - util.py[DEBUG]: loaded blob returned None, returning default.
2019-02-12 23:18:19,162 - util.py[DEBUG]: Reading from /sys/class/net/eth0/address (quiet=False)
2019-02-12 23:18:19,162 - util.py[DEBUG]: Read 18 bytes from /sys/class/net/eth0/address
2019-02-12 23:18:19,163 - stages.py[DEBUG]: applying net config names for {'version': 1, 'config': [{'subnets': [{'type': 'dhcp4'}], 'type': 'physical', 'name': 'eth0', 'mac_address': '12:4d:02:3b:2f:5e'}]}
2019-02-12 23:18:19,163 - stages.py[DEBUG]: Using distro class <class 'cloudinit.distros.rhel.Distro'>
2019-02-12 23:18:19,163 - util.py[DEBUG]: Reading from /sys/class/net/eth0/device/device (quiet=False)
2019-02-12 23:18:19,163 - util.py[DEBUG]: Reading from /sys/class/net/eth0/addr_assign_type (quiet=False)
2019-02-12 23:18:19,163 - util.py[DEBUG]: Read 2 bytes from /sys/class/net/eth0/addr_assign_type
2019-02-12 23:18:19,163 - util.py[DEBUG]: Reading from /sys/class/net/eth0/uevent (quiet=False)
2019-02-12 23:18:19,164 - util.py[DEBUG]: Read 25 bytes from /sys/class/net/eth0/uevent
2019-02-12 23:18:19,164 - util.py[DEBUG]: Reading from /sys/class/net/eth0/address (quiet=False)
2019-02-12 23:18:19,164 - util.py[DEBUG]: Read 18 bytes from /sys/class/net/eth0/address
2019-02-12 23:18:19,164 - util.py[DEBUG]: Reading from /sys/class/net/eth0/device/device (quiet=False)
2019-02-12 23:18:19,164 - util.py[DEBUG]: Reading from /sys/class/net/lo/addr_assign_type (quiet=False)
2019-02-12 23:18:19,164 - util.py[DEBUG]: Read 2 bytes from /sys/class/net/lo/addr_assign_type
2019-02-12 23:18:19,164 - util.py[DEBUG]: Reading from /sys/class/net/lo/uevent (quiet=False)
2019-02-12 23:18:19,164 - util.py[DEBUG]: Read 23 bytes from /sys/class/net/lo/uevent
2019-02-12 23:18:19,164 - util.py[DEBUG]: Reading from /sys/class/net/lo/address (quiet=False)
2019-02-12 23:18:19,164 - util.py[DEBUG]: Read 18 bytes from /sys/class/net/lo/address
2019-02-12 23:18:19,165 - util.py[DEBUG]: Reading from /sys/class/net/lo/device/device (quiet=False)
2019-02-12 23:18:19,165 - util.py[DEBUG]: Reading from /sys/class/net/eth0/operstate (quiet=False)
2019-02-12 23:18:19,165 - util.py[DEBUG]: Read 3 bytes from /sys/class/net/eth0/operstate
2019-02-12 23:18:19,165 - util.py[DEBUG]: Reading from /sys/class/net/lo/operstate (quiet=False)
2019-02-12 23:18:19,165 - util.py[DEBUG]: Read 8 bytes from /sys/class/net/lo/operstate
2019-02-12 23:18:19,165 - util.py[DEBUG]: Running command ['ip', '-6', 'addr', 'show', 'permanent', 'scope', 'global'] with allowed return codes [0] (shell=False, capture=True)
2019-02-12 23:18:19,182 - util.py[DEBUG]: Running command ['ip', '-4', 'addr', 'show'] with allowed return codes [0] (shell=False, capture=True)
2019-02-12 23:18:19,201 - __init__.py[DEBUG]: no work necessary for renaming of [['12:4d:02:3b:2f:5e', 'eth0', 'vif', None]]
2019-02-12 23:18:19,201 - stages.py[DEBUG]: not a new instance. network config is not applied.
2019-02-12 23:18:19,201 - util.py[DEBUG]: Writing to /var/lib/cloud/instances/i-0cd230a0ccdebe749/user-data.txt - wb: [600] 0 bytes
2019-02-12 23:18:19,202 - util.py[DEBUG]: Restoring selinux mode for /var/lib/cloud/instances/i-0cd230a0ccdebe749/user-data.txt (recursive=False)
2019-02-12 23:18:19,202 - util.py[DEBUG]: Restoring selinux mode for /var/lib/cloud/instances/i-0cd230a0ccdebe749/user-data.txt (recursive=False)
2019-02-12 23:18:19,226 - util.py[DEBUG]: Writing to /var/lib/cloud/instances/i-0cd230a0ccdebe749/user-data.txt.i - wb: [600] 344 bytes
2019-02-12 23:18:19,227 - util.py[DEBUG]: Restoring selinux mode for /var/lib/cloud/instances/i-0cd230a0ccdebe749/user-data.txt.i (recursive=False)
2019-02-12 23:18:19,227 - util.py[DEBUG]: Restoring selinux mode for /var/lib/cloud/instances/i-0cd230a0ccdebe749/user-data.txt.i (recursive=False)
2019-02-12 23:18:19,228 - util.py[DEBUG]: Writing to /var/lib/cloud/instances/i-0cd230a0ccdebe749/vendor-data.txt - wb: [600] 0 bytes
2019-02-12 23:18:19,228 - util.py[DEBUG]: Restoring selinux mode for /var/lib/cloud/instances/i-0cd230a0ccdebe749/vendor-data.txt (recursive=False)
2019-02-12 23:18:19,229 - util.py[DEBUG]: Restoring selinux mode for /var/lib/cloud/instances/i-0cd230a0ccdebe749/vendor-data.txt (recursive=False)
2019-02-12 23:18:19,230 - util.py[DEBUG]: Writing to /var/lib/cloud/instances/i-0cd230a0ccdebe749/vendor-data.txt.i - wb: [600] 344 bytes
2019-02-12 23:18:19,230 - util.py[DEBUG]: Restoring selinux mode for /var/lib/cloud/instances/i-0cd230a0ccdebe749/vendor-data.txt.i (recursive=False)
2019-02-12 23:18:19,231 - util.py[DEBUG]: Restoring selinux mode for /var/lib/cloud/instances/i-0cd230a0ccdebe749/vendor-data.txt.i (recursive=False)
2019-02-12 23:18:19,232 - util.py[DEBUG]: Reading from /var/lib/cloud/data/set-hostname (quiet=False)
2019-02-12 23:18:19,232 - util.py[DEBUG]: Read 79 bytes from /var/lib/cloud/data/set-hostname
2019-02-12 23:18:19,232 - cc_set_hostname.py[DEBUG]: No hostname changes. Skipping set-hostname
2019-02-12 23:18:19,232 - util.py[DEBUG]: Writing to /var/lib/cloud/instances/i-0cd230a0ccdebe749/sem/consume_data - wb: [644] 20 bytes
2019-02-12 23:18:19,233 - util.py[DEBUG]: Restoring selinux mode for /var/lib/cloud/instances/i-0cd230a0ccdebe749/sem/consume_data (recursive=False)
2019-02-12 23:18:19,233 - util.py[DEBUG]: Restoring selinux mode for /var/lib/cloud/instances/i-0cd230a0ccdebe749/sem/consume_data (recursive=False)
2019-02-12 23:18:19,233 - helpers.py[DEBUG]: Running consume_data using lock (<FileLock using file '/var/lib/cloud/instances/i-0cd230a0ccdebe749/sem/consume_data'>)
2019-02-12 23:18:19,234 - handlers.py[DEBUG]: start: init-network/consume-user-data: reading and applying user-data
2019-02-12 23:18:19,234 - launch_index.py[DEBUG]: Discarding 0 multipart messages which do not match launch index 0
2019-02-12 23:18:19,234 - stages.py[DEBUG]: Added default handler for set(['text/cloud-config-jsonp', 'text/cloud-config']) from CloudConfigPartHandler: [['text/cloud-config', 'text/cloud-config-jsonp']]
2019-02-12 23:18:19,240 - stages.py[DEBUG]: Added default handler for set(['text/x-shellscript']) from ShellScriptPartHandler: [['text/x-shellscript']]
2019-02-12 23:18:19,240 - stages.py[DEBUG]: Added default handler for set(['text/cloud-boothook']) from BootHookPartHandler: [['text/cloud-boothook']]
2019-02-12 23:18:19,240 - stages.py[DEBUG]: Added default handler for set(['text/upstart-job']) from UpstartJobPartHandler: [['text/upstart-job']]
2019-02-12 23:18:19,240 - __init__.py[DEBUG]: Calling handler BootHookPartHandler: [['text/cloud-boothook']] (__begin__, None, 2) with frequency once-per-instance
2019-02-12 23:18:19,241 - __init__.py[DEBUG]: Calling handler UpstartJobPartHandler: [['text/upstart-job']] (__begin__, None, 2) with frequency once-per-instance
2019-02-12 23:18:19,241 - __init__.py[DEBUG]: Calling handler CloudConfigPartHandler: [['text/cloud-config', 'text/cloud-config-jsonp']] (__begin__, None, 3) with frequency once-per-instance
2019-02-12 23:18:19,241 - __init__.py[DEBUG]: Calling handler ShellScriptPartHandler: [['text/x-shellscript']] (__begin__, None, 2) with frequency once-per-instance
2019-02-12 23:18:19,241 - __init__.py[DEBUG]: {'Content-Type': 'text/x-not-multipart', 'Content-Disposition': 'attachment; filename="part-001"', 'MIME-Version': '1.0'}
2019-02-12 23:18:19,241 - __init__.py[DEBUG]: Empty payload of type text/x-not-multipart
2019-02-12 23:18:19,241 - __init__.py[DEBUG]: Calling handler BootHookPartHandler: [['text/cloud-boothook']] (__end__, None, 2) with frequency once-per-instance
2019-02-12 23:18:19,241 - __init__.py[DEBUG]: Calling handler UpstartJobPartHandler: [['text/upstart-job']] (__end__, None, 2) with frequency once-per-instance
2019-02-12 23:18:19,241 - __init__.py[DEBUG]: Calling handler CloudConfigPartHandler: [['text/cloud-config', 'text/cloud-config-jsonp']] (__end__, None, 3) with frequency once-per-instance
2019-02-12 23:18:19,241 - util.py[DEBUG]: Writing to /var/lib/cloud/instances/i-0cd230a0ccdebe749/cloud-config.txt - wb: [600] 0 bytes
2019-02-12 23:18:19,242 - util.py[DEBUG]: Restoring selinux mode for /var/lib/cloud/instances/i-0cd230a0ccdebe749/cloud-config.txt (recursive=False)
2019-02-12 23:18:19,242 - util.py[DEBUG]: Restoring selinux mode for /var/lib/cloud/instances/i-0cd230a0ccdebe749/cloud-config.txt (recursive=False)
2019-02-12 23:18:19,243 - __init__.py[DEBUG]: Calling handler ShellScriptPartHandler: [['text/x-shellscript']] (__end__, None, 2) with frequency once-per-instance
2019-02-12 23:18:19,243 - handlers.py[DEBUG]: finish: init-network/consume-user-data: SUCCESS: reading and applying user-data
2019-02-12 23:18:19,243 - handlers.py[DEBUG]: start: init-network/consume-vendor-data: reading and applying vendor-data
2019-02-12 23:18:19,243 - stages.py[DEBUG]: no vendordata from datasource
2019-02-12 23:18:19,243 - handlers.py[DEBUG]: finish: init-network/consume-vendor-data: SUCCESS: reading and applying vendor-data
2019-02-12 23:18:19,243 - util.py[DEBUG]: Reading from /etc/cloud/cloud.cfg (quiet=False)
2019-02-12 23:18:19,243 - util.py[DEBUG]: Read 1198 bytes from /etc/cloud/cloud.cfg
2019-02-12 23:18:19,243 - util.py[DEBUG]: Attempting to load yaml from string of length 1198 with allowed root types (<type 'dict'>,)
2019-02-12 23:18:19,266 - util.py[DEBUG]: Reading from /etc/cloud/cloud.cfg.d/05_logging.cfg (quiet=False)
2019-02-12 23:18:19,266 - util.py[DEBUG]: Read 1821 bytes from /etc/cloud/cloud.cfg.d/05_logging.cfg
2019-02-12 23:18:19,266 - util.py[DEBUG]: Attempting to load yaml from string of length 1821 with allowed root types (<type 'dict'>,)
2019-02-12 23:18:19,270 - util.py[DEBUG]: Reading from /run/cloud-init/cloud.cfg (quiet=False)
2019-02-12 23:18:19,270 - util.py[DEBUG]: Attempting to load yaml from string of length 0 with allowed root types (<type 'dict'>,)
2019-02-12 23:18:19,270 - util.py[DEBUG]: loaded blob returned None, returning default.
2019-02-12 23:18:19,270 - util.py[DEBUG]: Reading from /var/lib/cloud/instance/cloud-config.txt (quiet=False)
2019-02-12 23:18:19,270 - util.py[DEBUG]: Read 0 bytes from /var/lib/cloud/instance/cloud-config.txt
2019-02-12 23:18:19,270 - util.py[DEBUG]: Attempting to load yaml from string of length 0 with allowed root types (<type 'dict'>,)
2019-02-12 23:18:19,270 - util.py[DEBUG]: loaded blob returned None, returning default.
2019-02-12 23:18:19,271 - util.py[DEBUG]: Reading from /var/lib/cloud/instance/cloud-config.txt (quiet=False)
2019-02-12 23:18:19,271 - util.py[DEBUG]: Read 0 bytes from /var/lib/cloud/instance/cloud-config.txt
2019-02-12 23:18:19,271 - util.py[DEBUG]: Attempting to load yaml from string of length 0 with allowed root types (<type 'dict'>,)
2019-02-12 23:18:19,272 - util.py[DEBUG]: loaded blob returned None, returning default.
2019-02-12 23:18:19,274 - util.py[DEBUG]: Writing to /var/lib/cloud/instance/obj.pkl - wb: [400] 7710 bytes
2019-02-12 23:18:19,293 - util.py[DEBUG]: Restoring selinux mode for /var/lib/cloud/instances/i-0cd230a0ccdebe749/obj.pkl (recursive=False)
2019-02-12 23:18:19,294 - util.py[DEBUG]: Restoring selinux mode for /var/lib/cloud/instances/i-0cd230a0ccdebe749/obj.pkl (recursive=False)
2019-02-12 23:18:19,294 - main.py[DEBUG]: no di_report found in config.
2019-02-12 23:18:19,502 - stages.py[DEBUG]: Using distro class <class 'cloudinit.distros.rhel.Distro'>
2019-02-12 23:18:19,503 - stages.py[DEBUG]: Running module disk_setup (<module 'cloudinit.config.cc_disk_setup' from '/usr/lib/python2.7/site-packages/cloudinit/config/cc_disk_setup.pyc'>) with frequency once-per-instance
2019-02-12 23:18:19,503 - handlers.py[DEBUG]: start: init-network/config-disk_setup: running config-disk_setup with frequency once-per-instance
2019-02-12 23:18:19,503 - util.py[DEBUG]: Writing to /var/lib/cloud/instances/i-0cd230a0ccdebe749/sem/config_disk_setup - wb: [644] 19 bytes
2019-02-12 23:18:19,504 - util.py[DEBUG]: Restoring selinux mode for /var/lib/cloud/instances/i-0cd230a0ccdebe749/sem/config_disk_setup (recursive=False)
2019-02-12 23:18:19,504 - util.py[DEBUG]: Restoring selinux mode for /var/lib/cloud/instances/i-0cd230a0ccdebe749/sem/config_disk_setup (recursive=False)
2019-02-12 23:18:19,505 - helpers.py[DEBUG]: Running config-disk_setup using lock (<FileLock using file '/var/lib/cloud/instances/i-0cd230a0ccdebe749/sem/config_disk_setup'>)
2019-02-12 23:18:19,505 - handlers.py[DEBUG]: finish: init-network/config-disk_setup: SUCCESS: config-disk_setup ran successfully
2019-02-12 23:18:19,505 - stages.py[DEBUG]: Running module migrator (<module 'cloudinit.config.cc_migrator' from '/usr/lib/python2.7/site-packages/cloudinit/config/cc_migrator.pyc'>) with frequency always
2019-02-12 23:18:19,505 - handlers.py[DEBUG]: start: init-network/config-migrator: running config-migrator with frequency always
2019-02-12 23:18:19,505 - helpers.py[DEBUG]: Running config-migrator using lock (<cloudinit.helpers.DummyLock object at 0x7f18a4e03210>)
2019-02-12 23:18:19,505 - cc_migrator.py[DEBUG]: Migrated 0 semaphore files to there canonicalized names
2019-02-12 23:18:19,505 - handlers.py[DEBUG]: finish: init-network/config-migrator: SUCCESS: config-migrator ran successfully
2019-02-12 23:18:19,505 - stages.py[DEBUG]: Running module bootcmd (<module 'cloudinit.config.cc_bootcmd' from '/usr/lib/python2.7/site-packages/cloudinit/config/cc_bootcmd.pyc'>) with frequency always
2019-02-12 23:18:19,506 - handlers.py[DEBUG]: start: init-network/config-bootcmd: running config-bootcmd with frequency always
2019-02-12 23:18:19,506 - helpers.py[DEBUG]: Running config-bootcmd using lock (<cloudinit.helpers.DummyLock object at 0x7f18a4e032d0>)
2019-02-12 23:18:19,506 - cc_bootcmd.py[DEBUG]: Skipping module named bootcmd, no 'bootcmd' key in configuration
2019-02-12 23:18:19,506 - handlers.py[DEBUG]: finish: init-network/config-bootcmd: SUCCESS: config-bootcmd ran successfully
2019-02-12 23:18:19,506 - stages.py[DEBUG]: Running module write-files (<module 'cloudinit.config.cc_write_files' from '/usr/lib/python2.7/site-packages/cloudinit/config/cc_write_files.pyc'>) with frequency once-per-instance
2019-02-12 23:18:19,506 - handlers.py[DEBUG]: start: init-network/config-write-files: running config-write-files with frequency once-per-instance
2019-02-12 23:18:19,506 - util.py[DEBUG]: Writing to /var/lib/cloud/instances/i-0cd230a0ccdebe749/sem/config_write_files - wb: [644] 20 bytes
2019-02-12 23:18:19,507 - util.py[DEBUG]: Restoring selinux mode for /var/lib/cloud/instances/i-0cd230a0ccdebe749/sem/config_write_files (recursive=False)
2019-02-12 23:18:19,507 - util.py[DEBUG]: Restoring selinux mode for /var/lib/cloud/instances/i-0cd230a0ccdebe749/sem/config_write_files (recursive=False)
2019-02-12 23:18:19,508 - helpers.py[DEBUG]: Running config-write-files using lock (<FileLock using file '/var/lib/cloud/instances/i-0cd230a0ccdebe749/sem/config_write_files'>)
2019-02-12 23:18:19,508 - cc_write_files.py[DEBUG]: Skipping module named write-files, no/empty 'write_files' key in configuration
2019-02-12 23:18:19,508 - handlers.py[DEBUG]: finish: init-network/config-write-files: SUCCESS: config-write-files ran successfully
2019-02-12 23:18:19,508 - stages.py[DEBUG]: Running module growpart (<module 'cloudinit.config.cc_growpart' from '/usr/lib/python2.7/site-packages/cloudinit/config/cc_growpart.pyc'>) with frequency always
2019-02-12 23:18:19,508 - handlers.py[DEBUG]: start: init-network/config-growpart: running config-growpart with frequency always
2019-02-12 23:18:19,508 - helpers.py[DEBUG]: Running config-growpart using lock (<cloudinit.helpers.DummyLock object at 0x7f18a4e03390>)
2019-02-12 23:18:19,508 - cc_growpart.py[DEBUG]: No 'growpart' entry in cfg.  Using default: {'ignore_growroot_disabled': False, 'mode': 'auto', 'devices': ['/']}
2019-02-12 23:18:19,508 - util.py[DEBUG]: Running command ['growpart', '--help'] with allowed return codes [0] (shell=False, capture=True)
2019-02-12 23:18:19,536 - util.py[DEBUG]: Reading from /proc/3809/mountinfo (quiet=False)
2019-02-12 23:18:19,537 - util.py[DEBUG]: Read 2859 bytes from /proc/3809/mountinfo
2019-02-12 23:18:19,537 - util.py[DEBUG]: Running command ['systemd-detect-virt', '--quiet', '--container'] with allowed return codes [0] (shell=False, capture=True)
2019-02-12 23:18:19,540 - util.py[DEBUG]: Running command ['running-in-container'] with allowed return codes [0] (shell=False, capture=True)
2019-02-12 23:18:19,543 - util.py[DEBUG]: Running command ['lxc-is-container'] with allowed return codes [0] (shell=False, capture=True)
2019-02-12 23:18:19,545 - util.py[DEBUG]: Reading from /proc/1/environ (quiet=False)
2019-02-12 23:18:19,546 - util.py[DEBUG]: Read 0 bytes from /proc/1/environ
2019-02-12 23:18:19,546 - util.py[DEBUG]: Reading from /proc/self/status (quiet=False)
2019-02-12 23:18:19,546 - util.py[DEBUG]: Read 1188 bytes from /proc/self/status
2019-02-12 23:18:19,550 - util.py[DEBUG]: Reading from /sys/class/block/xvda1/partition (quiet=False)
2019-02-12 23:18:19,550 - util.py[DEBUG]: Read 2 bytes from /sys/class/block/xvda1/partition
2019-02-12 23:18:19,550 - util.py[DEBUG]: Reading from /sys/devices/vbd-768/block/xvda/dev (quiet=False)
2019-02-12 23:18:19,550 - util.py[DEBUG]: Read 6 bytes from /sys/devices/vbd-768/block/xvda/dev
2019-02-12 23:18:19,550 - util.py[DEBUG]: Running command ['growpart', '--dry-run', '/dev/xvda', '1'] with allowed return codes [0] (shell=False, capture=True)
2019-02-12 23:18:19,590 - util.py[DEBUG]: resize_devices took 0.054 seconds
2019-02-12 23:18:19,590 - cc_growpart.py[DEBUG]: '/' NOCHANGE: no change necessary (/dev/xvda, 1)
2019-02-12 23:18:19,590 - handlers.py[DEBUG]: finish: init-network/config-growpart: SUCCESS: config-growpart ran successfully
2019-02-12 23:18:19,590 - stages.py[DEBUG]: Running module resizefs (<module 'cloudinit.config.cc_resizefs' from '/usr/lib/python2.7/site-packages/cloudinit/config/cc_resizefs.pyc'>) with frequency always
2019-02-12 23:18:19,591 - handlers.py[DEBUG]: start: init-network/config-resizefs: running config-resizefs with frequency always
2019-02-12 23:18:19,591 - helpers.py[DEBUG]: Running config-resizefs using lock (<cloudinit.helpers.DummyLock object at 0x7f18a4e03950>)
2019-02-12 23:18:19,591 - schema.py[DEBUG]: Ignoring schema validation. python-jsonschema is not present
2019-02-12 23:18:19,591 - util.py[DEBUG]: Reading from /proc/3809/mountinfo (quiet=False)
2019-02-12 23:18:19,591 - util.py[DEBUG]: Read 2859 bytes from /proc/3809/mountinfo
2019-02-12 23:18:19,591 - cc_resizefs.py[DEBUG]: resize_info: dev=/dev/xvda1 mnt_point=/ path=/
2019-02-12 23:18:19,591 - util.py[DEBUG]: Running command ['systemd-detect-virt', '--quiet', '--container'] with allowed return codes [0] (shell=False, capture=True)
2019-02-12 23:18:19,594 - util.py[DEBUG]: Running command ['running-in-container'] with allowed return codes [0] (shell=False, capture=True)
2019-02-12 23:18:19,597 - util.py[DEBUG]: Running command ['lxc-is-container'] with allowed return codes [0] (shell=False, capture=True)
2019-02-12 23:18:19,600 - util.py[DEBUG]: Reading from /proc/1/environ (quiet=False)
2019-02-12 23:18:19,600 - util.py[DEBUG]: Read 0 bytes from /proc/1/environ
2019-02-12 23:18:19,600 - util.py[DEBUG]: Reading from /proc/self/status (quiet=False)
2019-02-12 23:18:19,600 - util.py[DEBUG]: Read 1188 bytes from /proc/self/status
2019-02-12 23:18:19,600 - cc_resizefs.py[DEBUG]: Resizing / (xfs) using xfs_growfs /
2019-02-12 23:18:19,601 - util.py[DEBUG]: Running command ('xfs_growfs', '/') with allowed return codes [0] (shell=False, capture=True)
2019-02-12 23:18:19,609 - util.py[DEBUG]: Resizing took 0.008 seconds
2019-02-12 23:18:19,609 - cc_resizefs.py[DEBUG]: Resized root filesystem (type=xfs, val=True)
2019-02-12 23:18:19,609 - handlers.py[DEBUG]: finish: init-network/config-resizefs: SUCCESS: config-resizefs ran successfully
2019-02-12 23:18:19,609 - stages.py[DEBUG]: Running module set_hostname (<module 'cloudinit.config.cc_set_hostname' from '/usr/lib/python2.7/site-packages/cloudinit/config/cc_set_hostname.pyc'>) with frequency once-per-instance
2019-02-12 23:18:19,610 - handlers.py[DEBUG]: start: init-network/config-set_hostname: running config-set_hostname with frequency once-per-instance
2019-02-12 23:18:19,610 - util.py[DEBUG]: Writing to /var/lib/cloud/instances/i-0cd230a0ccdebe749/sem/config_set_hostname - wb: [644] 20 bytes
2019-02-12 23:18:19,611 - util.py[DEBUG]: Restoring selinux mode for /var/lib/cloud/instances/i-0cd230a0ccdebe749/sem/config_set_hostname (recursive=False)
2019-02-12 23:18:19,611 - util.py[DEBUG]: Restoring selinux mode for /var/lib/cloud/instances/i-0cd230a0ccdebe749/sem/config_set_hostname (recursive=False)
2019-02-12 23:18:19,611 - helpers.py[DEBUG]: Running config-set_hostname using lock (<FileLock using file '/var/lib/cloud/instances/i-0cd230a0ccdebe749/sem/config_set_hostname'>)
2019-02-12 23:18:19,612 - util.py[DEBUG]: Reading from /var/lib/cloud/data/set-hostname (quiet=False)
2019-02-12 23:18:19,612 - util.py[DEBUG]: Read 79 bytes from /var/lib/cloud/data/set-hostname
2019-02-12 23:18:19,612 - cc_set_hostname.py[DEBUG]: No hostname changes. Skipping set-hostname
2019-02-12 23:18:19,612 - handlers.py[DEBUG]: finish: init-network/config-set_hostname: SUCCESS: config-set_hostname ran successfully
2019-02-12 23:18:19,612 - stages.py[DEBUG]: Running module update_hostname (<module 'cloudinit.config.cc_update_hostname' from '/usr/lib/python2.7/site-packages/cloudinit/config/cc_update_hostname.pyc'>) with frequency always
2019-02-12 23:18:19,612 - handlers.py[DEBUG]: start: init-network/config-update_hostname: running config-update_hostname with frequency always
2019-02-12 23:18:19,612 - helpers.py[DEBUG]: Running config-update_hostname using lock (<cloudinit.helpers.DummyLock object at 0x7f18a4e0e150>)
2019-02-12 23:18:19,612 - cc_update_hostname.py[DEBUG]: Updating hostname to ip-172-31-84-133.ec2.internal (ip-172-31-84-133)
2019-02-12 23:18:19,613 - util.py[DEBUG]: Running command ['hostname'] with allowed return codes [0] (shell=False, capture=True)
2019-02-12 23:18:19,615 - __init__.py[DEBUG]: Attempting to update hostname to ip-172-31-84-133.ec2.internal in 1 files
2019-02-12 23:18:19,615 - util.py[DEBUG]: Writing to /var/lib/cloud/data/previous-hostname - wb: [644] 29 bytes
2019-02-12 23:18:19,616 - util.py[DEBUG]: Restoring selinux mode for /var/lib/cloud/data/previous-hostname (recursive=False)
2019-02-12 23:18:19,616 - util.py[DEBUG]: Restoring selinux mode for /var/lib/cloud/data/previous-hostname (recursive=False)
2019-02-12 23:18:19,617 - handlers.py[DEBUG]: finish: init-network/config-update_hostname: SUCCESS: config-update_hostname ran successfully
2019-02-12 23:18:19,617 - stages.py[DEBUG]: Running module update_etc_hosts (<module 'cloudinit.config.cc_update_etc_hosts' from '/usr/lib/python2.7/site-packages/cloudinit/config/cc_update_etc_hosts.pyc'>) with frequency always
2019-02-12 23:18:19,617 - handlers.py[DEBUG]: start: init-network/config-update_etc_hosts: running config-update_etc_hosts with frequency always
2019-02-12 23:18:19,617 - helpers.py[DEBUG]: Running config-update_etc_hosts using lock (<cloudinit.helpers.DummyLock object at 0x7f18a4e0e210>)
2019-02-12 23:18:19,617 - cc_update_etc_hosts.py[DEBUG]: Configuration option 'manage_etc_hosts' is not set, not managing /etc/hosts in module update_etc_hosts
2019-02-12 23:18:19,617 - handlers.py[DEBUG]: finish: init-network/config-update_etc_hosts: SUCCESS: config-update_etc_hosts ran successfully
2019-02-12 23:18:19,617 - stages.py[DEBUG]: Running module rsyslog (<module 'cloudinit.config.cc_rsyslog' from '/usr/lib/python2.7/site-packages/cloudinit/config/cc_rsyslog.pyc'>) with frequency once-per-instance
2019-02-12 23:18:19,618 - handlers.py[DEBUG]: start: init-network/config-rsyslog: running config-rsyslog with frequency once-per-instance
2019-02-12 23:18:19,618 - util.py[DEBUG]: Writing to /var/lib/cloud/instances/i-0cd230a0ccdebe749/sem/config_rsyslog - wb: [644] 20 bytes
2019-02-12 23:18:19,618 - util.py[DEBUG]: Restoring selinux mode for /var/lib/cloud/instances/i-0cd230a0ccdebe749/sem/config_rsyslog (recursive=False)
2019-02-12 23:18:19,619 - util.py[DEBUG]: Restoring selinux mode for /var/lib/cloud/instances/i-0cd230a0ccdebe749/sem/config_rsyslog (recursive=False)
2019-02-12 23:18:19,619 - helpers.py[DEBUG]: Running config-rsyslog using lock (<FileLock using file '/var/lib/cloud/instances/i-0cd230a0ccdebe749/sem/config_rsyslog'>)
2019-02-12 23:18:19,619 - cc_rsyslog.py[DEBUG]: Skipping module named rsyslog, no 'rsyslog' key in configuration
2019-02-12 23:18:19,619 - handlers.py[DEBUG]: finish: init-network/config-rsyslog: SUCCESS: config-rsyslog ran successfully
2019-02-12 23:18:19,619 - stages.py[DEBUG]: Running module users-groups (<module 'cloudinit.config.cc_users_groups' from '/usr/lib/python2.7/site-packages/cloudinit/config/cc_users_groups.pyc'>) with frequency once-per-instance
2019-02-12 23:18:19,620 - handlers.py[DEBUG]: start: init-network/config-users-groups: running config-users-groups with frequency once-per-instance
2019-02-12 23:18:19,620 - util.py[DEBUG]: Writing to /var/lib/cloud/instances/i-0cd230a0ccdebe749/sem/config_users_groups - wb: [644] 20 bytes
2019-02-12 23:18:19,620 - util.py[DEBUG]: Restoring selinux mode for /var/lib/cloud/instances/i-0cd230a0ccdebe749/sem/config_users_groups (recursive=False)
2019-02-12 23:18:19,621 - util.py[DEBUG]: Restoring selinux mode for /var/lib/cloud/instances/i-0cd230a0ccdebe749/sem/config_users_groups (recursive=False)
2019-02-12 23:18:19,621 - helpers.py[DEBUG]: Running config-users-groups using lock (<FileLock using file '/var/lib/cloud/instances/i-0cd230a0ccdebe749/sem/config_users_groups'>)
2019-02-12 23:18:19,622 - util.py[DEBUG]: Reading from /etc/os-release (quiet=True)
2019-02-12 23:18:19,622 - util.py[DEBUG]: Read 393 bytes from /etc/os-release
2019-02-12 23:18:19,622 - util.py[DEBUG]: Reading from /etc/system-image/channel.ini (quiet=True)
2019-02-12 23:18:19,622 - util.py[DEBUG]: Read 0 bytes from /etc/system-image/channel.ini
2019-02-12 23:18:19,623 - __init__.py[DEBUG]: Adding user centos
2019-02-12 23:18:19,623 - util.py[DEBUG]: Running hidden command to protect sensitive input/output logstring: ['useradd', 'centos', '--comment', 'Cloud User', '--groups', 'adm,systemd-journal,wheel', '--shell', '/bin/bash', '-m']
2019-02-12 23:18:19,664 - util.py[DEBUG]: Running command ['passwd', '-l', 'centos'] with allowed return codes [0] (shell=False, capture=True)
2019-02-12 23:18:19,690 - util.py[DEBUG]: Reading from /etc/sudoers (quiet=False)
2019-02-12 23:18:19,691 - util.py[DEBUG]: Read 4328 bytes from /etc/sudoers
2019-02-12 23:18:19,692 - util.py[DEBUG]: Restoring selinux mode for /etc/sudoers.d (recursive=False)
2019-02-12 23:18:19,693 - util.py[DEBUG]: Writing to /etc/sudoers.d/90-cloud-init-users - wb: [440] 122 bytes
2019-02-12 23:18:19,693 - util.py[DEBUG]: Restoring selinux mode for /etc/sudoers.d/90-cloud-init-users (recursive=False)
2019-02-12 23:18:19,694 - util.py[DEBUG]: Restoring selinux mode for /etc/sudoers.d/90-cloud-init-users (recursive=False)
2019-02-12 23:18:19,694 - handlers.py[DEBUG]: finish: init-network/config-users-groups: SUCCESS: config-users-groups ran successfully
2019-02-12 23:18:19,694 - stages.py[DEBUG]: Running module ssh (<module 'cloudinit.config.cc_ssh' from '/usr/lib/python2.7/site-packages/cloudinit/config/cc_ssh.pyc'>) with frequency once-per-instance
2019-02-12 23:18:19,694 - handlers.py[DEBUG]: start: init-network/config-ssh: running config-ssh with frequency once-per-instance
2019-02-12 23:18:19,695 - util.py[DEBUG]: Writing to /var/lib/cloud/instances/i-0cd230a0ccdebe749/sem/config_ssh - wb: [644] 19 bytes
2019-02-12 23:18:19,695 - util.py[DEBUG]: Restoring selinux mode for /var/lib/cloud/instances/i-0cd230a0ccdebe749/sem/config_ssh (recursive=False)
2019-02-12 23:18:19,696 - util.py[DEBUG]: Restoring selinux mode for /var/lib/cloud/instances/i-0cd230a0ccdebe749/sem/config_ssh (recursive=False)
2019-02-12 23:18:19,696 - helpers.py[DEBUG]: Running config-ssh using lock (<FileLock using file '/var/lib/cloud/instances/i-0cd230a0ccdebe749/sem/config_ssh'>)
2019-02-12 23:18:19,697 - util.py[DEBUG]: Restoring selinux mode for /home/centos (recursive=True)
2019-02-12 23:18:19,698 - util.py[DEBUG]: Restoring selinux mode for /home/centos/.ssh (recursive=False)
2019-02-12 23:18:19,698 - util.py[DEBUG]: Changing the ownership of /home/centos/.ssh to 1000:1000
2019-02-12 23:18:19,698 - util.py[DEBUG]: Reading from /etc/ssh/sshd_config (quiet=False)
2019-02-12 23:18:19,698 - util.py[DEBUG]: Read 3907 bytes from /etc/ssh/sshd_config
2019-02-12 23:18:19,699 - util.py[DEBUG]: Restoring selinux mode for /home/centos/.ssh (recursive=True)
2019-02-12 23:18:19,699 - util.py[DEBUG]: Restoring selinux mode for /home/centos/.ssh (recursive=False)
2019-02-12 23:18:19,699 - util.py[DEBUG]: Writing to /home/centos/.ssh/authorized_keys - wb: [600] 393 bytes
2019-02-12 23:18:19,700 - util.py[DEBUG]: Restoring selinux mode for /home/centos/.ssh/authorized_keys (recursive=False)
2019-02-12 23:18:19,700 - util.py[DEBUG]: Restoring selinux mode for /home/centos/.ssh/authorized_keys (recursive=False)
2019-02-12 23:18:19,700 - util.py[DEBUG]: Changing the ownership of /home/centos/.ssh/authorized_keys to 1000:1000
2019-02-12 23:18:19,700 - util.py[DEBUG]: Restoring selinux mode for /home/centos/.ssh (recursive=True)
2019-02-12 23:18:19,701 - util.py[DEBUG]: Restoring selinux mode for /root (recursive=True)
2019-02-12 23:18:19,703 - util.py[DEBUG]: Restoring selinux mode for /root/.ssh (recursive=False)
2019-02-12 23:18:19,703 - util.py[DEBUG]: Changing the ownership of /root/.ssh to 0:0
2019-02-12 23:18:19,703 - util.py[DEBUG]: Reading from /etc/ssh/sshd_config (quiet=False)
2019-02-12 23:18:19,704 - util.py[DEBUG]: Read 3907 bytes from /etc/ssh/sshd_config
2019-02-12 23:18:19,704 - util.py[DEBUG]: Restoring selinux mode for /root/.ssh (recursive=True)
2019-02-12 23:18:19,704 - util.py[DEBUG]: Restoring selinux mode for /root/.ssh (recursive=False)
2019-02-12 23:18:19,704 - util.py[DEBUG]: Writing to /root/.ssh/authorized_keys - wb: [600] 548 bytes
2019-02-12 23:18:19,705 - util.py[DEBUG]: Restoring selinux mode for /root/.ssh/authorized_keys (recursive=False)
2019-02-12 23:18:19,705 - util.py[DEBUG]: Restoring selinux mode for /root/.ssh/authorized_keys (recursive=False)
2019-02-12 23:18:19,705 - util.py[DEBUG]: Changing the ownership of /root/.ssh/authorized_keys to 0:0
2019-02-12 23:18:19,705 - util.py[DEBUG]: Restoring selinux mode for /root/.ssh (recursive=True)
2019-02-12 23:18:19,705 - handlers.py[DEBUG]: finish: init-network/config-ssh: SUCCESS: config-ssh ran successfully
2019-02-12 23:18:19,705 - main.py[DEBUG]: Ran 12 modules with 0 failures
2019-02-12 23:18:19,706 - util.py[DEBUG]: Reading from /proc/uptime (quiet=False)
2019-02-12 23:18:19,706 - util.py[DEBUG]: Read 12 bytes from /proc/uptime
2019-02-12 23:18:19,706 - util.py[DEBUG]: cloud-init mode 'init' took 0.804 seconds (0.80)
2019-02-12 23:18:19,706 - handlers.py[DEBUG]: finish: init-network: SUCCESS: searching for network datasources
2019-02-12 23:18:20,540 - util.py[DEBUG]: Cloud-init v. 18.2 running 'modules:config' at Tue, 12 Feb 2019 23:18:20 +0000. Up 63.52 seconds.
2019-02-12 23:18:20,656 - stages.py[DEBUG]: Using distro class <class 'cloudinit.distros.rhel.Distro'>
2019-02-12 23:18:20,657 - stages.py[DEBUG]: Running module mounts (<module 'cloudinit.config.cc_mounts' from '/usr/lib/python2.7/site-packages/cloudinit/config/cc_mounts.pyc'>) with frequency once-per-instance
2019-02-12 23:18:20,657 - handlers.py[DEBUG]: start: modules-config/config-mounts: running config-mounts with frequency once-per-instance
2019-02-12 23:18:20,658 - util.py[DEBUG]: Writing to /var/lib/cloud/instances/i-0cd230a0ccdebe749/sem/config_mounts - wb: [644] 20 bytes
2019-02-12 23:18:20,659 - util.py[DEBUG]: Restoring selinux mode for /var/lib/cloud/instances/i-0cd230a0ccdebe749/sem/config_mounts (recursive=False)
2019-02-12 23:18:20,660 - util.py[DEBUG]: Restoring selinux mode for /var/lib/cloud/instances/i-0cd230a0ccdebe749/sem/config_mounts (recursive=False)
2019-02-12 23:18:20,660 - helpers.py[DEBUG]: Running config-mounts using lock (<FileLock using file '/var/lib/cloud/instances/i-0cd230a0ccdebe749/sem/config_mounts'>)
2019-02-12 23:18:20,660 - cc_mounts.py[DEBUG]: mounts configuration is []
2019-02-12 23:18:20,660 - cc_mounts.py[DEBUG]: Attempting to determine the real name of ephemeral0
2019-02-12 23:18:20,660 - DataSourceEc2.py[DEBUG]: Unable to convert ephemeral0 to a device
2019-02-12 23:18:20,661 - cc_mounts.py[DEBUG]: Ignoring nonexistant default named mount ephemeral0
2019-02-12 23:18:20,661 - cc_mounts.py[DEBUG]: Attempting to determine the real name of swap
2019-02-12 23:18:20,661 - DataSourceEc2.py[DEBUG]: Unable to convert swap to a device
2019-02-12 23:18:20,661 - cc_mounts.py[DEBUG]: Ignoring nonexistant default named mount swap
2019-02-12 23:18:20,661 - cc_mounts.py[DEBUG]: no need to setup swap
2019-02-12 23:18:20,661 - cc_mounts.py[DEBUG]: No modifications to fstab needed.
2019-02-12 23:18:20,661 - handlers.py[DEBUG]: finish: modules-config/config-mounts: SUCCESS: config-mounts ran successfully
2019-02-12 23:18:20,661 - stages.py[DEBUG]: Running module locale (<module 'cloudinit.config.cc_locale' from '/usr/lib/python2.7/site-packages/cloudinit/config/cc_locale.pyc'>) with frequency once-per-instance
2019-02-12 23:18:20,661 - handlers.py[DEBUG]: start: modules-config/config-locale: running config-locale with frequency once-per-instance
2019-02-12 23:18:20,661 - util.py[DEBUG]: Writing to /var/lib/cloud/instances/i-0cd230a0ccdebe749/sem/config_locale - wb: [644] 20 bytes
2019-02-12 23:18:20,662 - util.py[DEBUG]: Restoring selinux mode for /var/lib/cloud/instances/i-0cd230a0ccdebe749/sem/config_locale (recursive=False)
2019-02-12 23:18:20,662 - util.py[DEBUG]: Restoring selinux mode for /var/lib/cloud/instances/i-0cd230a0ccdebe749/sem/config_locale (recursive=False)
2019-02-12 23:18:20,663 - helpers.py[DEBUG]: Running config-locale using lock (<FileLock using file '/var/lib/cloud/instances/i-0cd230a0ccdebe749/sem/config_locale'>)
2019-02-12 23:18:20,663 - cc_locale.py[DEBUG]: Setting locale to en_US.UTF-8
2019-02-12 23:18:20,663 - util.py[DEBUG]: Reading from /etc/locale.conf (quiet=False)
2019-02-12 23:18:20,663 - util.py[DEBUG]: Read 19 bytes from /etc/locale.conf
2019-02-12 23:18:20,664 - util.py[DEBUG]: Writing to /etc/locale.conf - wb: [644] 17 bytes
2019-02-12 23:18:20,664 - util.py[DEBUG]: Restoring selinux mode for /etc/locale.conf (recursive=False)
2019-02-12 23:18:20,664 - util.py[DEBUG]: Restoring selinux mode for /etc/locale.conf (recursive=False)
2019-02-12 23:18:20,665 - handlers.py[DEBUG]: finish: modules-config/config-locale: SUCCESS: config-locale ran successfully
2019-02-12 23:18:20,665 - stages.py[DEBUG]: Running module set-passwords (<module 'cloudinit.config.cc_set_passwords' from '/usr/lib/python2.7/site-packages/cloudinit/config/cc_set_passwords.pyc'>) with frequency once-per-instance
2019-02-12 23:18:20,665 - handlers.py[DEBUG]: start: modules-config/config-set-passwords: running config-set-passwords with frequency once-per-instance
2019-02-12 23:18:20,665 - util.py[DEBUG]: Writing to /var/lib/cloud/instances/i-0cd230a0ccdebe749/sem/config_set_passwords - wb: [644] 20 bytes
2019-02-12 23:18:20,665 - util.py[DEBUG]: Restoring selinux mode for /var/lib/cloud/instances/i-0cd230a0ccdebe749/sem/config_set_passwords (recursive=False)
2019-02-12 23:18:20,666 - util.py[DEBUG]: Restoring selinux mode for /var/lib/cloud/instances/i-0cd230a0ccdebe749/sem/config_set_passwords (recursive=False)
2019-02-12 23:18:20,679 - helpers.py[DEBUG]: Running config-set-passwords using lock (<FileLock using file '/var/lib/cloud/instances/i-0cd230a0ccdebe749/sem/config_set_passwords'>)
2019-02-12 23:18:20,679 - util.py[DEBUG]: Reading from /etc/ssh/sshd_config (quiet=False)
2019-02-12 23:18:20,680 - util.py[DEBUG]: Read 3907 bytes from /etc/ssh/sshd_config
2019-02-12 23:18:20,680 - cc_set_passwords.py[DEBUG]: Replacing auth line 65 with no
2019-02-12 23:18:20,680 - util.py[DEBUG]: Writing to /etc/ssh/sshd_config - wb: [600] 3905 bytes
2019-02-12 23:18:20,681 - util.py[DEBUG]: Restoring selinux mode for /etc/ssh/sshd_config (recursive=False)
2019-02-12 23:18:20,681 - util.py[DEBUG]: Restoring selinux mode for /etc/ssh/sshd_config (recursive=False)
2019-02-12 23:18:20,681 - util.py[DEBUG]: Running command ['service', 'sshd', 'restart'] with allowed return codes [0] (shell=False, capture=True)
2019-02-12 23:18:20,754 - cc_set_passwords.py[DEBUG]: Restarted the ssh daemon
2019-02-12 23:18:20,754 - handlers.py[DEBUG]: finish: modules-config/config-set-passwords: SUCCESS: config-set-passwords ran successfully
2019-02-12 23:18:20,754 - stages.py[DEBUG]: Running module rh_subscription (<module 'cloudinit.config.cc_rh_subscription' from '/usr/lib/python2.7/site-packages/cloudinit/config/cc_rh_subscription.pyc'>) with frequency once-per-instance
2019-02-12 23:18:20,755 - handlers.py[DEBUG]: start: modules-config/config-rh_subscription: running config-rh_subscription with frequency once-per-instance
2019-02-12 23:18:20,755 - util.py[DEBUG]: Writing to /var/lib/cloud/instances/i-0cd230a0ccdebe749/sem/config_rh_subscription - wb: [644] 20 bytes
2019-02-12 23:18:20,756 - util.py[DEBUG]: Restoring selinux mode for /var/lib/cloud/instances/i-0cd230a0ccdebe749/sem/config_rh_subscription (recursive=False)
2019-02-12 23:18:20,756 - util.py[DEBUG]: Restoring selinux mode for /var/lib/cloud/instances/i-0cd230a0ccdebe749/sem/config_rh_subscription (recursive=False)
2019-02-12 23:18:20,756 - helpers.py[DEBUG]: Running config-rh_subscription using lock (<FileLock using file '/var/lib/cloud/instances/i-0cd230a0ccdebe749/sem/config_rh_subscription'>)
2019-02-12 23:18:20,757 - cc_rh_subscription.py[DEBUG]: rh_subscription: module not configured.
2019-02-12 23:18:20,757 - handlers.py[DEBUG]: finish: modules-config/config-rh_subscription: SUCCESS: config-rh_subscription ran successfully
2019-02-12 23:18:20,757 - stages.py[DEBUG]: Running module yum-add-repo (<module 'cloudinit.config.cc_yum_add_repo' from '/usr/lib/python2.7/site-packages/cloudinit/config/cc_yum_add_repo.pyc'>) with frequency once-per-instance
2019-02-12 23:18:20,757 - handlers.py[DEBUG]: start: modules-config/config-yum-add-repo: running config-yum-add-repo with frequency once-per-instance
2019-02-12 23:18:20,757 - util.py[DEBUG]: Writing to /var/lib/cloud/instances/i-0cd230a0ccdebe749/sem/config_yum_add_repo - wb: [644] 20 bytes
2019-02-12 23:18:20,758 - util.py[DEBUG]: Restoring selinux mode for /var/lib/cloud/instances/i-0cd230a0ccdebe749/sem/config_yum_add_repo (recursive=False)
2019-02-12 23:18:20,758 - util.py[DEBUG]: Restoring selinux mode for /var/lib/cloud/instances/i-0cd230a0ccdebe749/sem/config_yum_add_repo (recursive=False)
2019-02-12 23:18:20,758 - helpers.py[DEBUG]: Running config-yum-add-repo using lock (<FileLock using file '/var/lib/cloud/instances/i-0cd230a0ccdebe749/sem/config_yum_add_repo'>)
2019-02-12 23:18:20,758 - cc_yum_add_repo.py[DEBUG]: Skipping module named yum-add-repo, no 'yum_repos' configuration found
2019-02-12 23:18:20,759 - handlers.py[DEBUG]: finish: modules-config/config-yum-add-repo: SUCCESS: config-yum-add-repo ran successfully
2019-02-12 23:18:20,759 - stages.py[DEBUG]: Running module package-update-upgrade-install (<module 'cloudinit.config.cc_package_update_upgrade_install' from '/usr/lib/python2.7/site-packages/cloudinit/config/cc_package_update_upgrade_install.pyc'>) with frequency once-per-instance
2019-02-12 23:18:20,759 - handlers.py[DEBUG]: start: modules-config/config-package-update-upgrade-install: running config-package-update-upgrade-install with frequency once-per-instance
2019-02-12 23:18:20,759 - util.py[DEBUG]: Writing to /var/lib/cloud/instances/i-0cd230a0ccdebe749/sem/config_package_update_upgrade_install - wb: [644] 20 bytes
2019-02-12 23:18:20,759 - util.py[DEBUG]: Restoring selinux mode for /var/lib/cloud/instances/i-0cd230a0ccdebe749/sem/config_package_update_upgrade_install (recursive=False)
2019-02-12 23:18:20,760 - util.py[DEBUG]: Restoring selinux mode for /var/lib/cloud/instances/i-0cd230a0ccdebe749/sem/config_package_update_upgrade_install (recursive=False)
2019-02-12 23:18:20,760 - helpers.py[DEBUG]: Running config-package-update-upgrade-install using lock (<FileLock using file '/var/lib/cloud/instances/i-0cd230a0ccdebe749/sem/config_package_update_upgrade_install'>)
2019-02-12 23:18:20,760 - handlers.py[DEBUG]: finish: modules-config/config-package-update-upgrade-install: SUCCESS: config-package-update-upgrade-install ran successfully
2019-02-12 23:18:20,760 - stages.py[DEBUG]: Running module timezone (<module 'cloudinit.config.cc_timezone' from '/usr/lib/python2.7/site-packages/cloudinit/config/cc_timezone.pyc'>) with frequency once-per-instance
2019-02-12 23:18:20,761 - handlers.py[DEBUG]: start: modules-config/config-timezone: running config-timezone with frequency once-per-instance
2019-02-12 23:18:20,761 - util.py[DEBUG]: Writing to /var/lib/cloud/instances/i-0cd230a0ccdebe749/sem/config_timezone - wb: [644] 20 bytes
2019-02-12 23:18:20,761 - util.py[DEBUG]: Restoring selinux mode for /var/lib/cloud/instances/i-0cd230a0ccdebe749/sem/config_timezone (recursive=False)
2019-02-12 23:18:20,762 - util.py[DEBUG]: Restoring selinux mode for /var/lib/cloud/instances/i-0cd230a0ccdebe749/sem/config_timezone (recursive=False)
2019-02-12 23:18:20,762 - helpers.py[DEBUG]: Running config-timezone using lock (<FileLock using file '/var/lib/cloud/instances/i-0cd230a0ccdebe749/sem/config_timezone'>)
2019-02-12 23:18:20,762 - cc_timezone.py[DEBUG]: Skipping module named timezone, no 'timezone' specified
2019-02-12 23:18:20,764 - handlers.py[DEBUG]: finish: modules-config/config-timezone: SUCCESS: config-timezone ran successfully
2019-02-12 23:18:20,764 - stages.py[DEBUG]: Running module puppet (<module 'cloudinit.config.cc_puppet' from '/usr/lib/python2.7/site-packages/cloudinit/config/cc_puppet.pyc'>) with frequency once-per-instance
2019-02-12 23:18:20,764 - handlers.py[DEBUG]: start: modules-config/config-puppet: running config-puppet with frequency once-per-instance
2019-02-12 23:18:20,764 - util.py[DEBUG]: Writing to /var/lib/cloud/instances/i-0cd230a0ccdebe749/sem/config_puppet - wb: [644] 20 bytes
2019-02-12 23:18:20,764 - util.py[DEBUG]: Restoring selinux mode for /var/lib/cloud/instances/i-0cd230a0ccdebe749/sem/config_puppet (recursive=False)
2019-02-12 23:18:20,765 - util.py[DEBUG]: Restoring selinux mode for /var/lib/cloud/instances/i-0cd230a0ccdebe749/sem/config_puppet (recursive=False)
2019-02-12 23:18:20,765 - helpers.py[DEBUG]: Running config-puppet using lock (<FileLock using file '/var/lib/cloud/instances/i-0cd230a0ccdebe749/sem/config_puppet'>)
2019-02-12 23:18:20,765 - cc_puppet.py[DEBUG]: Skipping module named puppet, no 'puppet' configuration found
2019-02-12 23:18:20,765 - handlers.py[DEBUG]: finish: modules-config/config-puppet: SUCCESS: config-puppet ran successfully
2019-02-12 23:18:20,766 - stages.py[DEBUG]: Running module chef (<module 'cloudinit.config.cc_chef' from '/usr/lib/python2.7/site-packages/cloudinit/config/cc_chef.pyc'>) with frequency once-per-instance
2019-02-12 23:18:20,766 - handlers.py[DEBUG]: start: modules-config/config-chef: running config-chef with frequency once-per-instance
2019-02-12 23:18:20,766 - util.py[DEBUG]: Writing to /var/lib/cloud/instances/i-0cd230a0ccdebe749/sem/config_chef - wb: [644] 20 bytes
2019-02-12 23:18:20,766 - util.py[DEBUG]: Restoring selinux mode for /var/lib/cloud/instances/i-0cd230a0ccdebe749/sem/config_chef (recursive=False)
2019-02-12 23:18:20,767 - util.py[DEBUG]: Restoring selinux mode for /var/lib/cloud/instances/i-0cd230a0ccdebe749/sem/config_chef (recursive=False)
2019-02-12 23:18:20,767 - helpers.py[DEBUG]: Running config-chef using lock (<FileLock using file '/var/lib/cloud/instances/i-0cd230a0ccdebe749/sem/config_chef'>)
2019-02-12 23:18:20,767 - cc_chef.py[DEBUG]: Skipping module named chef, no 'chef' key in configuration
2019-02-12 23:18:20,767 - handlers.py[DEBUG]: finish: modules-config/config-chef: SUCCESS: config-chef ran successfully
2019-02-12 23:18:20,767 - stages.py[DEBUG]: Running module salt-minion (<module 'cloudinit.config.cc_salt_minion' from '/usr/lib/python2.7/site-packages/cloudinit/config/cc_salt_minion.pyc'>) with frequency once-per-instance
2019-02-12 23:18:20,768 - handlers.py[DEBUG]: start: modules-config/config-salt-minion: running config-salt-minion with frequency once-per-instance
2019-02-12 23:18:20,768 - util.py[DEBUG]: Writing to /var/lib/cloud/instances/i-0cd230a0ccdebe749/sem/config_salt_minion - wb: [644] 20 bytes
2019-02-12 23:18:20,768 - util.py[DEBUG]: Restoring selinux mode for /var/lib/cloud/instances/i-0cd230a0ccdebe749/sem/config_salt_minion (recursive=False)
2019-02-12 23:18:20,769 - util.py[DEBUG]: Restoring selinux mode for /var/lib/cloud/instances/i-0cd230a0ccdebe749/sem/config_salt_minion (recursive=False)
2019-02-12 23:18:20,769 - helpers.py[DEBUG]: Running config-salt-minion using lock (<FileLock using file '/var/lib/cloud/instances/i-0cd230a0ccdebe749/sem/config_salt_minion'>)
2019-02-12 23:18:20,769 - cc_salt_minion.py[DEBUG]: Skipping module named salt-minion, no 'salt_minion' key in configuration
2019-02-12 23:18:20,769 - handlers.py[DEBUG]: finish: modules-config/config-salt-minion: SUCCESS: config-salt-minion ran successfully
2019-02-12 23:18:20,769 - stages.py[DEBUG]: Running module mcollective (<module 'cloudinit.config.cc_mcollective' from '/usr/lib/python2.7/site-packages/cloudinit/config/cc_mcollective.pyc'>) with frequency once-per-instance
2019-02-12 23:18:20,769 - handlers.py[DEBUG]: start: modules-config/config-mcollective: running config-mcollective with frequency once-per-instance
2019-02-12 23:18:20,770 - util.py[DEBUG]: Writing to /var/lib/cloud/instances/i-0cd230a0ccdebe749/sem/config_mcollective - wb: [644] 20 bytes
2019-02-12 23:18:20,770 - util.py[DEBUG]: Restoring selinux mode for /var/lib/cloud/instances/i-0cd230a0ccdebe749/sem/config_mcollective (recursive=False)
2019-02-12 23:18:20,771 - util.py[DEBUG]: Restoring selinux mode for /var/lib/cloud/instances/i-0cd230a0ccdebe749/sem/config_mcollective (recursive=False)
2019-02-12 23:18:20,771 - helpers.py[DEBUG]: Running config-mcollective using lock (<FileLock using file '/var/lib/cloud/instances/i-0cd230a0ccdebe749/sem/config_mcollective'>)
2019-02-12 23:18:20,771 - cc_mcollective.py[DEBUG]: Skipping module named mcollective, no 'mcollective' key in configuration
2019-02-12 23:18:20,771 - handlers.py[DEBUG]: finish: modules-config/config-mcollective: SUCCESS: config-mcollective ran successfully
2019-02-12 23:18:20,771 - stages.py[DEBUG]: Running module disable-ec2-metadata (<module 'cloudinit.config.cc_disable_ec2_metadata' from '/usr/lib/python2.7/site-packages/cloudinit/config/cc_disable_ec2_metadata.pyc'>) with frequency always
2019-02-12 23:18:20,771 - handlers.py[DEBUG]: start: modules-config/config-disable-ec2-metadata: running config-disable-ec2-metadata with frequency always
2019-02-12 23:18:20,771 - helpers.py[DEBUG]: Running config-disable-ec2-metadata using lock (<cloudinit.helpers.DummyLock object at 0x7f2a86266e50>)
2019-02-12 23:18:20,772 - cc_disable_ec2_metadata.py[DEBUG]: Skipping module named disable-ec2-metadata, disabling the ec2 route not enabled
2019-02-12 23:18:20,772 - handlers.py[DEBUG]: finish: modules-config/config-disable-ec2-metadata: SUCCESS: config-disable-ec2-metadata ran successfully
2019-02-12 23:18:20,772 - stages.py[DEBUG]: Running module runcmd (<module 'cloudinit.config.cc_runcmd' from '/usr/lib/python2.7/site-packages/cloudinit/config/cc_runcmd.pyc'>) with frequency once-per-instance
2019-02-12 23:18:20,772 - handlers.py[DEBUG]: start: modules-config/config-runcmd: running config-runcmd with frequency once-per-instance
2019-02-12 23:18:20,772 - util.py[DEBUG]: Writing to /var/lib/cloud/instances/i-0cd230a0ccdebe749/sem/config_runcmd - wb: [644] 20 bytes
2019-02-12 23:18:20,773 - util.py[DEBUG]: Restoring selinux mode for /var/lib/cloud/instances/i-0cd230a0ccdebe749/sem/config_runcmd (recursive=False)
2019-02-12 23:18:20,773 - util.py[DEBUG]: Restoring selinux mode for /var/lib/cloud/instances/i-0cd230a0ccdebe749/sem/config_runcmd (recursive=False)
2019-02-12 23:18:20,773 - helpers.py[DEBUG]: Running config-runcmd using lock (<FileLock using file '/var/lib/cloud/instances/i-0cd230a0ccdebe749/sem/config_runcmd'>)
2019-02-12 23:18:20,773 - cc_runcmd.py[DEBUG]: Skipping module named runcmd, no 'runcmd' key in configuration
2019-02-12 23:18:20,774 - handlers.py[DEBUG]: finish: modules-config/config-runcmd: SUCCESS: config-runcmd ran successfully
2019-02-12 23:18:20,774 - main.py[DEBUG]: Ran 13 modules with 0 failures
2019-02-12 23:18:20,774 - util.py[DEBUG]: Reading from /proc/uptime (quiet=False)
2019-02-12 23:18:20,774 - util.py[DEBUG]: Read 12 bytes from /proc/uptime
2019-02-12 23:18:20,774 - util.py[DEBUG]: cloud-init mode 'modules' took 0.389 seconds (0.39)
2019-02-12 23:18:20,774 - handlers.py[DEBUG]: finish: modules-config: SUCCESS: running modules for config
2019-02-12 23:18:21,013 - util.py[DEBUG]: Cloud-init v. 18.2 running 'modules:final' at Tue, 12 Feb 2019 23:18:20 +0000. Up 64.09 seconds.
2019-02-12 23:18:21,049 - stages.py[DEBUG]: Using distro class <class 'cloudinit.distros.rhel.Distro'>
2019-02-12 23:18:21,050 - stages.py[DEBUG]: Running module rightscale_userdata (<module 'cloudinit.config.cc_rightscale_userdata' from '/usr/lib/python2.7/site-packages/cloudinit/config/cc_rightscale_userdata.pyc'>) with frequency once-per-instance
2019-02-12 23:18:21,050 - handlers.py[DEBUG]: start: modules-final/config-rightscale_userdata: running config-rightscale_userdata with frequency once-per-instance
2019-02-12 23:18:21,050 - util.py[DEBUG]: Writing to /var/lib/cloud/instances/i-0cd230a0ccdebe749/sem/config_rightscale_userdata - wb: [644] 20 bytes
2019-02-12 23:18:21,051 - util.py[DEBUG]: Restoring selinux mode for /var/lib/cloud/instances/i-0cd230a0ccdebe749/sem/config_rightscale_userdata (recursive=False)
2019-02-12 23:18:21,051 - util.py[DEBUG]: Restoring selinux mode for /var/lib/cloud/instances/i-0cd230a0ccdebe749/sem/config_rightscale_userdata (recursive=False)
2019-02-12 23:18:21,052 - helpers.py[DEBUG]: Running config-rightscale_userdata using lock (<FileLock using file '/var/lib/cloud/instances/i-0cd230a0ccdebe749/sem/config_rightscale_userdata'>)
2019-02-12 23:18:21,052 - cc_rightscale_userdata.py[DEBUG]: Failed to get raw userdata in module rightscale_userdata
2019-02-12 23:18:21,052 - handlers.py[DEBUG]: finish: modules-final/config-rightscale_userdata: SUCCESS: config-rightscale_userdata ran successfully
2019-02-12 23:18:21,052 - stages.py[DEBUG]: Running module scripts-per-once (<module 'cloudinit.config.cc_scripts_per_once' from '/usr/lib/python2.7/site-packages/cloudinit/config/cc_scripts_per_once.pyc'>) with frequency once
2019-02-12 23:18:21,052 - handlers.py[DEBUG]: start: modules-final/config-scripts-per-once: running config-scripts-per-once with frequency once
2019-02-12 23:18:21,052 - util.py[DEBUG]: Writing to /var/lib/cloud/sem/config_scripts_per_once.once - wb: [644] 20 bytes
2019-02-12 23:18:21,053 - util.py[DEBUG]: Restoring selinux mode for /var/lib/cloud/sem/config_scripts_per_once.once (recursive=False)
2019-02-12 23:18:21,053 - util.py[DEBUG]: Restoring selinux mode for /var/lib/cloud/sem/config_scripts_per_once.once (recursive=False)
2019-02-12 23:18:21,053 - helpers.py[DEBUG]: Running config-scripts-per-once using lock (<FileLock using file '/var/lib/cloud/sem/config_scripts_per_once.once'>)
2019-02-12 23:18:21,054 - handlers.py[DEBUG]: finish: modules-final/config-scripts-per-once: SUCCESS: config-scripts-per-once ran successfully
2019-02-12 23:18:21,054 - stages.py[DEBUG]: Running module scripts-per-boot (<module 'cloudinit.config.cc_scripts_per_boot' from '/usr/lib/python2.7/site-packages/cloudinit/config/cc_scripts_per_boot.pyc'>) with frequency always
2019-02-12 23:18:21,054 - handlers.py[DEBUG]: start: modules-final/config-scripts-per-boot: running config-scripts-per-boot with frequency always
2019-02-12 23:18:21,054 - helpers.py[DEBUG]: Running config-scripts-per-boot using lock (<cloudinit.helpers.DummyLock object at 0x7f26932ad9d0>)
2019-02-12 23:18:21,054 - handlers.py[DEBUG]: finish: modules-final/config-scripts-per-boot: SUCCESS: config-scripts-per-boot ran successfully
2019-02-12 23:18:21,054 - stages.py[DEBUG]: Running module scripts-per-instance (<module 'cloudinit.config.cc_scripts_per_instance' from '/usr/lib/python2.7/site-packages/cloudinit/config/cc_scripts_per_instance.pyc'>) with frequency once-per-instance
2019-02-12 23:18:21,055 - handlers.py[DEBUG]: start: modules-final/config-scripts-per-instance: running config-scripts-per-instance with frequency once-per-instance
2019-02-12 23:18:21,055 - util.py[DEBUG]: Writing to /var/lib/cloud/instances/i-0cd230a0ccdebe749/sem/config_scripts_per_instance - wb: [644] 20 bytes
2019-02-12 23:18:21,055 - util.py[DEBUG]: Restoring selinux mode for /var/lib/cloud/instances/i-0cd230a0ccdebe749/sem/config_scripts_per_instance (recursive=False)
2019-02-12 23:18:21,056 - util.py[DEBUG]: Restoring selinux mode for /var/lib/cloud/instances/i-0cd230a0ccdebe749/sem/config_scripts_per_instance (recursive=False)
2019-02-12 23:18:21,056 - helpers.py[DEBUG]: Running config-scripts-per-instance using lock (<FileLock using file '/var/lib/cloud/instances/i-0cd230a0ccdebe749/sem/config_scripts_per_instance'>)
2019-02-12 23:18:21,056 - handlers.py[DEBUG]: finish: modules-final/config-scripts-per-instance: SUCCESS: config-scripts-per-instance ran successfully
2019-02-12 23:18:21,056 - stages.py[DEBUG]: Running module scripts-user (<module 'cloudinit.config.cc_scripts_user' from '/usr/lib/python2.7/site-packages/cloudinit/config/cc_scripts_user.pyc'>) with frequency once-per-instance
2019-02-12 23:18:21,056 - handlers.py[DEBUG]: start: modules-final/config-scripts-user: running config-scripts-user with frequency once-per-instance
2019-02-12 23:18:21,057 - util.py[DEBUG]: Writing to /var/lib/cloud/instances/i-0cd230a0ccdebe749/sem/config_scripts_user - wb: [644] 20 bytes
2019-02-12 23:18:21,057 - util.py[DEBUG]: Restoring selinux mode for /var/lib/cloud/instances/i-0cd230a0ccdebe749/sem/config_scripts_user (recursive=False)
2019-02-12 23:18:21,058 - util.py[DEBUG]: Restoring selinux mode for /var/lib/cloud/instances/i-0cd230a0ccdebe749/sem/config_scripts_user (recursive=False)
2019-02-12 23:18:21,058 - helpers.py[DEBUG]: Running config-scripts-user using lock (<FileLock using file '/var/lib/cloud/instances/i-0cd230a0ccdebe749/sem/config_scripts_user'>)
2019-02-12 23:18:21,058 - handlers.py[DEBUG]: finish: modules-final/config-scripts-user: SUCCESS: config-scripts-user ran successfully
2019-02-12 23:18:21,058 - stages.py[DEBUG]: Running module ssh-authkey-fingerprints (<module 'cloudinit.config.cc_ssh_authkey_fingerprints' from '/usr/lib/python2.7/site-packages/cloudinit/config/cc_ssh_authkey_fingerprints.pyc'>) with frequency once-per-instance
2019-02-12 23:18:21,058 - handlers.py[DEBUG]: start: modules-final/config-ssh-authkey-fingerprints: running config-ssh-authkey-fingerprints with frequency once-per-instance
2019-02-12 23:18:21,058 - util.py[DEBUG]: Writing to /var/lib/cloud/instances/i-0cd230a0ccdebe749/sem/config_ssh_authkey_fingerprints - wb: [644] 20 bytes
2019-02-12 23:18:21,059 - util.py[DEBUG]: Restoring selinux mode for /var/lib/cloud/instances/i-0cd230a0ccdebe749/sem/config_ssh_authkey_fingerprints (recursive=False)
2019-02-12 23:18:21,059 - util.py[DEBUG]: Restoring selinux mode for /var/lib/cloud/instances/i-0cd230a0ccdebe749/sem/config_ssh_authkey_fingerprints (recursive=False)
2019-02-12 23:18:21,060 - helpers.py[DEBUG]: Running config-ssh-authkey-fingerprints using lock (<FileLock using file '/var/lib/cloud/instances/i-0cd230a0ccdebe749/sem/config_ssh_authkey_fingerprints'>)
2019-02-12 23:18:21,060 - util.py[DEBUG]: Reading from /etc/ssh/sshd_config (quiet=False)
2019-02-12 23:18:21,061 - util.py[DEBUG]: Read 3905 bytes from /etc/ssh/sshd_config
2019-02-12 23:18:21,061 - util.py[DEBUG]: Restoring selinux mode for /home/centos/.ssh (recursive=True)
2019-02-12 23:18:21,062 - util.py[DEBUG]: Reading from /home/centos/.ssh/authorized_keys (quiet=False)
2019-02-12 23:18:21,062 - util.py[DEBUG]: Read 393 bytes from /home/centos/.ssh/authorized_keys
2019-02-12 23:18:21,093 - handlers.py[DEBUG]: finish: modules-final/config-ssh-authkey-fingerprints: SUCCESS: config-ssh-authkey-fingerprints ran successfully
2019-02-12 23:18:21,093 - stages.py[DEBUG]: Running module keys-to-console (<module 'cloudinit.config.cc_keys_to_console' from '/usr/lib/python2.7/site-packages/cloudinit/config/cc_keys_to_console.pyc'>) with frequency once-per-instance
2019-02-12 23:18:21,094 - handlers.py[DEBUG]: start: modules-final/config-keys-to-console: running config-keys-to-console with frequency once-per-instance
2019-02-12 23:18:21,094 - util.py[DEBUG]: Writing to /var/lib/cloud/instances/i-0cd230a0ccdebe749/sem/config_keys_to_console - wb: [644] 20 bytes
2019-02-12 23:18:21,094 - util.py[DEBUG]: Restoring selinux mode for /var/lib/cloud/instances/i-0cd230a0ccdebe749/sem/config_keys_to_console (recursive=False)
2019-02-12 23:18:21,095 - util.py[DEBUG]: Restoring selinux mode for /var/lib/cloud/instances/i-0cd230a0ccdebe749/sem/config_keys_to_console (recursive=False)
2019-02-12 23:18:21,095 - helpers.py[DEBUG]: Running config-keys-to-console using lock (<FileLock using file '/var/lib/cloud/instances/i-0cd230a0ccdebe749/sem/config_keys_to_console'>)
2019-02-12 23:18:21,095 - util.py[DEBUG]: Running command ['/usr/libexec/cloud-init/write-ssh-key-fingerprints', '', 'ssh-dss'] with allowed return codes [0] (shell=False, capture=True)
2019-02-12 23:18:21,165 - handlers.py[DEBUG]: finish: modules-final/config-keys-to-console: SUCCESS: config-keys-to-console ran successfully
2019-02-12 23:18:21,165 - stages.py[DEBUG]: Running module phone-home (<module 'cloudinit.config.cc_phone_home' from '/usr/lib/python2.7/site-packages/cloudinit/config/cc_phone_home.pyc'>) with frequency once-per-instance
2019-02-12 23:18:21,166 - handlers.py[DEBUG]: start: modules-final/config-phone-home: running config-phone-home with frequency once-per-instance
2019-02-12 23:18:21,166 - util.py[DEBUG]: Writing to /var/lib/cloud/instances/i-0cd230a0ccdebe749/sem/config_phone_home - wb: [644] 20 bytes
2019-02-12 23:18:21,167 - util.py[DEBUG]: Restoring selinux mode for /var/lib/cloud/instances/i-0cd230a0ccdebe749/sem/config_phone_home (recursive=False)
2019-02-12 23:18:21,167 - util.py[DEBUG]: Restoring selinux mode for /var/lib/cloud/instances/i-0cd230a0ccdebe749/sem/config_phone_home (recursive=False)
2019-02-12 23:18:21,167 - helpers.py[DEBUG]: Running config-phone-home using lock (<FileLock using file '/var/lib/cloud/instances/i-0cd230a0ccdebe749/sem/config_phone_home'>)
2019-02-12 23:18:21,168 - cc_phone_home.py[DEBUG]: Skipping module named phone-home, no 'phone_home' configuration found
2019-02-12 23:18:21,168 - handlers.py[DEBUG]: finish: modules-final/config-phone-home: SUCCESS: config-phone-home ran successfully
2019-02-12 23:18:21,168 - stages.py[DEBUG]: Running module final-message (<module 'cloudinit.config.cc_final_message' from '/usr/lib/python2.7/site-packages/cloudinit/config/cc_final_message.pyc'>) with frequency always
2019-02-12 23:18:21,168 - handlers.py[DEBUG]: start: modules-final/config-final-message: running config-final-message with frequency always
2019-02-12 23:18:21,168 - helpers.py[DEBUG]: Running config-final-message using lock (<cloudinit.helpers.DummyLock object at 0x7f26932bc0d0>)
2019-02-12 23:18:21,168 - util.py[DEBUG]: Reading from /proc/uptime (quiet=False)
2019-02-12 23:18:21,168 - util.py[DEBUG]: Read 12 bytes from /proc/uptime
2019-02-12 23:18:21,172 - util.py[DEBUG]: Cloud-init v. 18.2 finished at Tue, 12 Feb 2019 23:18:21 +0000. Datasource DataSourceEc2Local.  Up 64.29 seconds
2019-02-12 23:18:21,172 - util.py[DEBUG]: Writing to /var/lib/cloud/instance/boot-finished - wb: [644] 50 bytes
2019-02-12 23:18:21,172 - util.py[DEBUG]: Restoring selinux mode for /var/lib/cloud/instances/i-0cd230a0ccdebe749/boot-finished (recursive=False)
2019-02-12 23:18:21,173 - util.py[DEBUG]: Restoring selinux mode for /var/lib/cloud/instances/i-0cd230a0ccdebe749/boot-finished (recursive=False)
2019-02-12 23:18:21,173 - handlers.py[DEBUG]: finish: modules-final/config-final-message: SUCCESS: config-final-message ran successfully
2019-02-12 23:18:21,173 - stages.py[DEBUG]: Running module power-state-change (<module 'cloudinit.config.cc_power_state_change' from '/usr/lib/python2.7/site-packages/cloudinit/config/cc_power_state_change.pyc'>) with frequency once-per-instance
2019-02-12 23:18:21,174 - handlers.py[DEBUG]: start: modules-final/config-power-state-change: running config-power-state-change with frequency once-per-instance
2019-02-12 23:18:21,174 - util.py[DEBUG]: Writing to /var/lib/cloud/instances/i-0cd230a0ccdebe749/sem/config_power_state_change - wb: [644] 20 bytes
2019-02-12 23:18:21,174 - util.py[DEBUG]: Restoring selinux mode for /var/lib/cloud/instances/i-0cd230a0ccdebe749/sem/config_power_state_change (recursive=False)
2019-02-12 23:18:21,175 - util.py[DEBUG]: Restoring selinux mode for /var/lib/cloud/instances/i-0cd230a0ccdebe749/sem/config_power_state_change (recursive=False)
2019-02-12 23:18:21,175 - helpers.py[DEBUG]: Running config-power-state-change using lock (<FileLock using file '/var/lib/cloud/instances/i-0cd230a0ccdebe749/sem/config_power_state_change'>)
2019-02-12 23:18:21,175 - cc_power_state_change.py[DEBUG]: no power_state provided. doing nothing
2019-02-12 23:18:21,175 - handlers.py[DEBUG]: finish: modules-final/config-power-state-change: SUCCESS: config-power-state-change ran successfully
2019-02-12 23:18:21,183 - main.py[DEBUG]: Ran 10 modules with 0 failures
2019-02-12 23:18:21,183 - util.py[DEBUG]: Creating symbolic link from '/run/cloud-init/result.json' => '../../var/lib/cloud/data/result.json'
2019-02-12 23:18:21,184 - util.py[DEBUG]: Reading from /proc/uptime (quiet=False)
2019-02-12 23:18:21,184 - util.py[DEBUG]: Read 12 bytes from /proc/uptime
2019-02-12 23:18:21,184 - util.py[DEBUG]: cloud-init mode 'modules' took 0.220 seconds (0.22)
2019-02-12 23:18:21,184 - handlers.py[DEBUG]: finish: modules-final: SUCCESS: running modules for final
